<sdf version='1.7'>
  <world name='default'>
    <light name='sun' type='directional'>
      <cast_shadows>1</cast_shadows>
      <pose>0 0 10 0 -0 0</pose>
      <diffuse>0.8 0.8 0.8 1</diffuse>
      <specular>0.2 0.2 0.2 1</specular>
      <attenuation>
        <range>1000</range>
        <constant>0.9</constant>
        <linear>0.01</linear>
        <quadratic>0.001</quadratic>
      </attenuation>
      <direction>-0.5 0.1 -0.9</direction>
      <spot>
        <inner_angle>0</inner_angle>
        <outer_angle>0</outer_angle>
        <falloff>0</falloff>
      </spot>
    </light>
    <model name='ground_plane'>
      <static>1</static>
      <link name='link'>
        <collision name='collision'>
          <geometry>
            <plane>
              <normal>0 0 1</normal>
              <size>100 100</size>
            </plane>
          </geometry>
          <surface>
            <contact>
              <collide_bitmask>65535</collide_bitmask>
              <ode/>
            </contact>
            <friction>
              <ode>
                <mu>100</mu>
                <mu2>50</mu2>
              </ode>
              <torsional>
                <ode/>
              </torsional>
            </friction>
            <bounce/>
          </surface>
          <max_contacts>10</max_contacts>
        </collision>
        <visual name='visual'>
          <cast_shadows>0</cast_shadows>
          <geometry>
            <plane>
              <normal>0 0 1</normal>
              <size>100 100</size>
            </plane>
          </geometry>
          <material>
            <script>
              <uri>file://media/materials/scripts/gazebo.material</uri>
              <name>Gazebo/Grey</name>
            </script>
          </material>
        </visual>
        <self_collide>0</self_collide>
        <enable_wind>0</enable_wind>
        <kinematic>0</kinematic>
      </link>
    </model>
    <gravity>0 0 -9.8</gravity>
    <magnetic_field>6e-06 2.3e-05 -4.2e-05</magnetic_field>
    <atmosphere type='adiabatic'/>
    <physics type='ode'>
      <max_step_size>0.001</max_step_size>
      <real_time_factor>1</real_time_factor>
      <real_time_update_rate>1000</real_time_update_rate>
    </physics>
    <scene>
      <ambient>0.4 0.4 0.4 1</ambient>
      <background>0.7 0.7 0.7 1</background>
      <shadows>1</shadows>
    </scene>
    <wind/>
    <spherical_coordinates>
      <surface_model>EARTH_WGS84</surface_model>
      <latitude_deg>0</latitude_deg>
      <longitude_deg>0</longitude_deg>
      <elevation>0</elevation>
      <heading_deg>0</heading_deg>
    </spherical_coordinates>
    <model name='maze'>
      <pose>0.515 0.725 0 0 -0 0</pose>
      <link name='Wall_1'>
        <collision name='Wall_1_Collision'>
          <geometry>
            <box>
              <size>7 0.15 2.5</size>
            </box>
          </geometry>
          <pose>0 0 1.25 0 -0 0</pose>
          <max_contacts>10</max_contacts>
          <surface>
            <contact>
              <ode/>
            </contact>
            <bounce/>
            <friction>
              <torsional>
                <ode/>
              </torsional>
              <ode/>
            </friction>
          </surface>
        </collision>
        <visual name='Wall_1_Visual'>
          <pose>0 0 1.25 0 -0 0</pose>
          <geometry>
            <box>
              <size>7 0.15 2.5</size>
            </box>
          </geometry>
          <material>
            <script>
              <uri>file://media/materials/scripts/gazebo.material</uri>
              <name>Gazebo/Grey</name>
            </script>
            <ambient>1 1 1 1</ambient>
          </material>
          <meta>
            <layer>0</layer>
          </meta>
        </visual>
        <pose>0 -1.675 0 0 -0 0</pose>
        <self_collide>0</self_collide>
        <enable_wind>0</enable_wind>
        <kinematic>0</kinematic>
      </link>
      <link name='Wall_2'>
        <collision name='Wall_2_Collision'>
          <geometry>
            <box>
              <size>3.5 0.15 2.5</size>
            </box>
          </geometry>
          <pose>0 0 1.25 0 -0 0</pose>
          <max_contacts>10</max_contacts>
          <surface>
            <contact>
              <ode/>
            </contact>
            <bounce/>
            <friction>
              <torsional>
                <ode/>
              </torsional>
              <ode/>
            </friction>
          </surface>
        </collision>
        <visual name='Wall_2_Visual'>
          <pose>0 0 1.25 0 -0 0</pose>
          <geometry>
            <box>
              <size>3.5 0.15 2.5</size>
            </box>
          </geometry>
          <material>
            <script>
              <uri>file://media/materials/scripts/gazebo.material</uri>
              <name>Gazebo/Grey</name>
            </script>
            <ambient>1 1 1 1</ambient>
          </material>
          <meta>
            <layer>0</layer>
          </meta>
        </visual>
        <pose>3.425 -0 0 0 -0 1.5708</pose>
        <self_collide>0</self_collide>
        <enable_wind>0</enable_wind>
        <kinematic>0</kinematic>
      </link>
      <link name='Wall_3'>
        <collision name='Wall_3_Collision'>
          <geometry>
            <box>
              <size>7 0.15 2.5</size>
            </box>
          </geometry>
          <pose>0 0 1.25 0 -0 0</pose>
          <max_contacts>10</max_contacts>
          <surface>
            <contact>
              <ode/>
            </contact>
            <bounce/>
            <friction>
              <torsional>
                <ode/>
              </torsional>
              <ode/>
            </friction>
          </surface>
        </collision>
        <visual name='Wall_3_Visual'>
          <pose>0 0 1.25 0 -0 0</pose>
          <geometry>
            <box>
              <size>7 0.15 2.5</size>
            </box>
          </geometry>
          <material>
            <script>
              <uri>file://media/materials/scripts/gazebo.material</uri>
              <name>Gazebo/Grey</name>
            </script>
            <ambient>1 1 1 1</ambient>
          </material>
          <meta>
            <layer>0</layer>
          </meta>
        </visual>
        <pose>0 1.675 0 0 -0 3.14159</pose>
        <self_collide>0</self_collide>
        <enable_wind>0</enable_wind>
        <kinematic>0</kinematic>
      </link>
      <link name='Wall_4'>
        <collision name='Wall_4_Collision'>
          <geometry>
            <box>
              <size>3.5 0.15 2.5</size>
            </box>
          </geometry>
          <pose>0 0 1.25 0 -0 0</pose>
          <max_contacts>10</max_contacts>
          <surface>
            <contact>
              <ode/>
            </contact>
            <bounce/>
            <friction>
              <torsional>
                <ode/>
              </torsional>
              <ode/>
            </friction>
          </surface>
        </collision>
        <visual name='Wall_4_Visual'>
          <pose>0 0 1.25 0 -0 0</pose>
          <geometry>
            <box>
              <size>3.5 0.15 2.5</size>
            </box>
          </geometry>
          <material>
            <script>
              <uri>file://media/materials/scripts/gazebo.material</uri>
              <name>Gazebo/Grey</name>
            </script>
            <ambient>1 1 1 1</ambient>
          </material>
          <meta>
            <layer>0</layer>
          </meta>
        </visual>
        <pose>-3.425 -0 0 0 -0 -1.5708</pose>
        <self_collide>0</self_collide>
        <enable_wind>0</enable_wind>
        <kinematic>0</kinematic>
      </link>
      <link name='Wall_6'>
        <pose>1.095 -0 0 0 -0 -1.5708</pose>
        <visual name='Wall_6_Visual_0'>
          <pose>-0.7375 0 1.25 0 -0 0</pose>
          <geometry>
            <box>
              <size>2.025 0.15 2.5</size>
            </box>
          </geometry>
          <material>
            <script>
              <uri>file://media/materials/scripts/gazebo.material</uri>
              <name>Gazebo/Grey</name>
            </script>
            <ambient>1 1 1 1</ambient>
          </material>
          <meta>
            <layer>0</layer>
          </meta>
        </visual>
        <collision name='Wall_6_Collision_0'>
          <geometry>
            <box>
              <size>2.025 0.15 2.5</size>
            </box>
          </geometry>
          <pose>-0.7375 0 1.25 0 -0 0</pose>
          <max_contacts>10</max_contacts>
          <surface>
            <contact>
              <ode/>
            </contact>
            <bounce/>
            <friction>
              <torsional>
                <ode/>
              </torsional>
              <ode/>
            </friction>
          </surface>
        </collision>
        <visual name='Wall_6_Visual_1'>
          <pose>1.4625 0 1.25 0 -0 0</pose>
          <geometry>
            <box>
              <size>0.575 0.15 2.5</size>
            </box>
          </geometry>
          <material>
            <script>
              <uri>file://media/materials/scripts/gazebo.material</uri>
              <name>Gazebo/Grey</name>
            </script>
            <ambient>1 1 1 1</ambient>
          </material>
          <meta>
            <layer>0</layer>
          </meta>
        </visual>
        <collision name='Wall_6_Collision_1'>
          <geometry>
            <box>
              <size>0.575 0.15 2.5</size>
            </box>
          </geometry>
          <pose>1.4625 0 1.25 0 -0 0</pose>
          <max_contacts>10</max_contacts>
          <surface>
            <contact>
              <ode/>
            </contact>
            <bounce/>
            <friction>
              <torsional>
                <ode/>
              </torsional>
              <ode/>
            </friction>
          </surface>
        </collision>
        <visual name='Wall_6_Visual_2'>
          <pose>0.725 0 2.25 0 -0 0</pose>
          <geometry>
            <box>
              <size>0.9 0.15 0.5</size>
            </box>
          </geometry>
          <material>
            <script>
              <uri>file://media/materials/scripts/gazebo.material</uri>
              <name>Gazebo/Grey</name>
            </script>
            <ambient>1 1 1 1</ambient>
          </material>
          <meta>
            <layer>0</layer>
          </meta>
        </visual>
        <collision name='Wall_6_Collision_2'>
          <geometry>
            <box>
              <size>0.9 0.15 0.5</size>
            </box>
          </geometry>
          <pose>0.725 0 2.25 0 -0 0</pose>
          <max_contacts>10</max_contacts>
          <surface>
            <contact>
              <ode/>
            </contact>
            <bounce/>
            <friction>
              <torsional>
                <ode/>
              </torsional>
              <ode/>
            </friction>
          </surface>
        </collision>
        <self_collide>0</self_collide>
        <enable_wind>0</enable_wind>
        <kinematic>0</kinematic>
      </link>
      <static>1</static>
    </model>
    <gui fullscreen='0'>
      <camera name='user_camera'>
        <pose>2.50093 -0.196382 1.4217 0 0.725797 1.34817</pose>
        <view_controller>orbit</view_controller>
        <projection_type>perspective</projection_type>
      </camera>
    </gui>
    <model name='locobot'>
      <link name='locobot/base_footprint'>
        <inertial>
          <pose>0.005104 0.000172 0.071513 0 -0 0</pose>
          <mass>2.5355</mass>
          <inertia>
            <ixx>0.0191138</ixx>
            <ixy>-1.9875e-05</ixy>
            <ixz>0.000243647</ixz>
            <iyy>0.0181694</iyy>
            <iyz>-5.62795e-06</iyz>
            <izz>0.0353169</izz>
          </inertia>
        </inertial>
        <collision name='locobot/base_footprint_fixed_joint_lump__create3_base_collision_collision'>
          <pose>0 0 0.0492 0 -0 1.5708</pose>
          <geometry>
            <cylinder>
              <length>0.06</length>
              <radius>0.164</radius>
            </cylinder>
          </geometry>
          <max_contacts>10</max_contacts>
          <surface>
            <contact>
              <ode/>
            </contact>
            <bounce/>
            <friction>
              <torsional>
                <ode/>
              </torsional>
              <ode/>
            </friction>
          </surface>
        </collision>
        <collision name='locobot/base_footprint_fixed_joint_lump__locobot/bump_caster_link_collision_1'>
          <pose>-0.1098 0 0.009648 3.14159 -0 1.5708</pose>
          <geometry>
            <mesh>
              <scale>1 1 1</scale>
              <uri>/home/bharat/catkin_ws/src/interbotix_ros_rovers/interbotix_ros_xslocobots/interbotix_xslocobot_descriptions/meshes/locobot_meshes/create3_version/bump_caster.stl</uri>
            </mesh>
          </geometry>
          <max_contacts>10</max_contacts>
          <surface>
            <contact>
              <ode/>
            </contact>
            <bounce/>
            <friction>
              <torsional>
                <ode/>
              </torsional>
              <ode/>
            </friction>
          </surface>
        </collision>
        <visual name='locobot/base_footprint_fixed_joint_lump__locobot/base_link_visual'>
          <pose>0 0 0.0392 0 -0 1.5708</pose>
          <geometry>
            <mesh>
              <scale>1 1 1</scale>
              <uri>/home/bharat/catkin_ws/src/create3_sim_ros1/irobot_create_common/irobot_create_description/meshes/body_visual.dae</uri>
            </mesh>
          </geometry>
        </visual>
        <visual name='locobot/base_footprint_fixed_joint_lump__locobot/bump_caster_link_visual_1'>
          <pose>-0.1098 0 0.009648 3.14159 -0 1.5708</pose>
          <geometry>
            <mesh>
              <scale>1 1 1</scale>
              <uri>/home/bharat/catkin_ws/src/interbotix_ros_rovers/interbotix_ros_xslocobots/interbotix_xslocobot_descriptions/meshes/locobot_meshes/create3_version/bump_caster.stl</uri>
            </mesh>
          </geometry>
        </visual>
        <sensor name='imu' type='imu'>
          <always_on>1</always_on>
          <update_rate>62</update_rate>
          <imu>
            <angular_velocity>
              <x>
                <noise type='gaussian'>
                  <mean>0</mean>
                  <stddev>0</stddev>
                </noise>
              </x>
              <y>
                <noise type='gaussian'>
                  <mean>0</mean>
                  <stddev>0</stddev>
                </noise>
              </y>
              <z>
                <noise type='gaussian'>
                  <mean>0</mean>
                  <stddev>0</stddev>
                </noise>
              </z>
            </angular_velocity>
            <linear_acceleration>
              <x>
                <noise type='gaussian'>
                  <mean>0</mean>
                  <stddev>0</stddev>
                </noise>
              </x>
              <y>
                <noise type='gaussian'>
                  <mean>0</mean>
                  <stddev>0</stddev>
                </noise>
              </y>
              <z>
                <noise type='gaussian'>
                  <mean>0</mean>
                  <stddev>0</stddev>
                </noise>
              </z>
            </linear_acceleration>
          </imu>
          <pose>0.050613 0.043673 0.0844 0 -0 0</pose>
        </sensor>
        <self_collide>0</self_collide>
        <enable_wind>0</enable_wind>
        <kinematic>0</kinematic>
      </link>
      <joint name='bump_front_center_joint' type='fixed'>
        <pose relative_to='locobot/base_footprint'>0 0 0.0392 0 -0 0</pose>
        <parent>locobot/base_footprint</parent>
        <child>locobot/bump_front_center</child>
        <axis>
          <dynamics>
            <spring_reference>0</spring_reference>
            <spring_stiffness>0</spring_stiffness>
          </dynamics>
          <xyz>0 0 1</xyz>
          <limit>
            <lower>-1e+16</lower>
            <upper>1e+16</upper>
          </limit>
        </axis>
        <physics>
          <ode>
            <limit>
              <cfm>0</cfm>
              <erp>0.2</erp>
            </limit>
          </ode>
        </physics>
      </joint>
      <link name='locobot/bump_front_center'>
        <pose relative_to='bump_front_center_joint'>0 0 0 0 -0 0</pose>
        <inertial>
          <pose>0.08 0 0.02 0 -0 0</pose>
          <mass>0.1</mass>
          <inertia>
            <ixx>0.00134838</ixx>
            <ixy>4.54352e-08</ixy>
            <ixz>1.44348e-06</ixz>
            <iyy>0.000252174</iyy>
            <iyz>-6.721e-10</iyz>
            <izz>0.00154425</izz>
          </inertia>
        </inertial>
        <collision name='locobot/bump_front_center_collision'>
          <pose>0 0 0 0 -0 0</pose>
          <geometry>
            <mesh>
              <scale>1 1 1</scale>
              <uri>/home/bharat/catkin_ws/src/create3_sim_ros1/irobot_create_common/irobot_create_description/meshes/bumper_collision.dae</uri>
            </mesh>
          </geometry>
          <surface>
            <contact>
              <ode>
                <max_vel>0.01</max_vel>
                <min_depth>0.001</min_depth>
              </ode>
            </contact>
            <friction>
              <ode>
                <mu>0.1</mu>
                <mu2>0.1</mu2>
              </ode>
              <torsional>
                <ode/>
              </torsional>
            </friction>
            <bounce/>
          </surface>
          <max_contacts>10</max_contacts>
        </collision>
        <visual name='locobot/bump_front_center_visual'>
          <pose>0 0 0 0 -0 0</pose>
          <geometry>
            <mesh>
              <scale>1 1 1</scale>
              <uri>/home/bharat/catkin_ws/src/create3_sim_ros1/irobot_create_common/irobot_create_description/meshes/bumper_visual.dae</uri>
            </mesh>
          </geometry>
          <material>
            <script>
              <name>Gazebo/DarkGrey</name>
              <uri>file://media/materials/scripts/gazebo.material</uri>
            </script>
          </material>
        </visual>
        <sensor name='bump_front_center_contact_sensor' type='contact'>
          <always_on>1</always_on>
          <update_rate>62</update_rate>
          <contact>
            <collision>bump_front_center_collision</collision>
            <topic>__default_topic__</topic>
          </contact>
        </sensor>
        <self_collide>0</self_collide>
        <enable_wind>0</enable_wind>
        <kinematic>0</kinematic>
      </link>
      <joint name='camera_tower' type='revolute'>
        <pose relative_to='locobot/base_footprint'>-0.048271 0 0.10087 0 -0 0</pose>
        <parent>locobot/base_footprint</parent>
        <child>locobot/camera_tower_link</child>
        <axis>
          <limit>
            <lower>0</lower>
            <upper>0</upper>
          </limit>
          <dynamics>
            <damping>0</damping>
            <friction>0</friction>
            <spring_reference>0</spring_reference>
            <spring_stiffness>0</spring_stiffness>
          </dynamics>
          <xyz>0 0 1</xyz>
        </axis>
        <physics>
          <ode>
            <limit>
              <cfm>0</cfm>
              <erp>0.2</erp>
            </limit>
          </ode>
        </physics>
      </joint>
      <link name='locobot/camera_tower_link'>
        <pose relative_to='camera_tower'>0 0 0 0 -0 0</pose>
        <inertial>
          <pose>-0.024689 -0.003432 0.185408 0 -0 0</pose>
          <mass>2.43065</mass>
          <inertia>
            <ixx>0.0563</ixx>
            <ixy>0.000137</ixy>
            <ixz>0.00575</ixz>
            <iyy>0.0478</iyy>
            <iyz>-0.00077</iyz>
            <izz>0.0186</izz>
          </inertia>
        </inertial>
        <collision name='locobot/camera_tower_link_collision'>
          <pose>0 0 0 0 -0 0</pose>
          <geometry>
            <mesh>
              <scale>1 1 1</scale>
              <uri>/home/bharat/catkin_ws/src/interbotix_ros_rovers/interbotix_ros_xslocobots/interbotix_xslocobot_descriptions/meshes/locobot_meshes/create3_version/locobot_camera_tower_small_simple.stl</uri>
            </mesh>
          </geometry>
          <surface>
            <contact>
              <ode/>
            </contact>
            <friction>
              <ode/>
              <torsional>
                <ode/>
              </torsional>
            </friction>
            <bounce/>
          </surface>
          <max_contacts>10</max_contacts>
        </collision>
        <visual name='locobot/camera_tower_link_visual'>
          <pose>0 0 0 0 -0 0</pose>
          <geometry>
            <mesh>
              <scale>1 1 1</scale>
              <uri>/home/bharat/catkin_ws/src/interbotix_ros_rovers/interbotix_ros_xslocobots/interbotix_xslocobot_descriptions/meshes/locobot_meshes/create3_version/locobot_camera_tower_small.stl</uri>
            </mesh>
          </geometry>
          <material>
            <script>
              <name>Custom/Interbotix</name>
              <uri>file://media/materials/scripts/gazebo.material</uri>
            </script>
          </material>
        </visual>
        <self_collide>0</self_collide>
        <enable_wind>0</enable_wind>
        <kinematic>0</kinematic>
      </link>
      <joint name='arm_cradle' type='revolute'>
        <pose relative_to='locobot/camera_tower_link'>0.037943 0 0.139 0 -0 0</pose>
        <parent>locobot/camera_tower_link</parent>
        <child>locobot/arm_cradle_link</child>
        <axis>
          <limit>
            <lower>0</lower>
            <upper>0</upper>
          </limit>
          <dynamics>
            <damping>0</damping>
            <friction>0</friction>
            <spring_reference>0</spring_reference>
            <spring_stiffness>0</spring_stiffness>
          </dynamics>
          <xyz>0 0 1</xyz>
        </axis>
        <physics>
          <ode>
            <limit>
              <cfm>0</cfm>
              <erp>0.2</erp>
            </limit>
          </ode>
        </physics>
      </joint>
      <link name='locobot/arm_cradle_link'>
        <pose relative_to='arm_cradle'>0 0 0 0 -0 0</pose>
        <inertial>
          <pose>0.001439 0 0.009839 0 -0 0</pose>
          <mass>0.017626</mass>
          <inertia>
            <ixx>4.6575e-06</ixx>
            <ixy>0</ixy>
            <ixz>7.48e-08</ixz>
            <iyy>1.8629e-06</iyy>
            <iyz>0</iyz>
            <izz>4.6198e-06</izz>
          </inertia>
        </inertial>
        <collision name='locobot/arm_cradle_link_collision'>
          <pose>0 0 0 0 -0 0</pose>
          <geometry>
            <mesh>
              <scale>0.001 0.001 0.001</scale>
              <uri>/home/bharat/catkin_ws/src/interbotix_ros_rovers/interbotix_ros_xslocobots/interbotix_xslocobot_descriptions/meshes/locobot_meshes/locobot_arm_cradle.stl</uri>
            </mesh>
          </geometry>
          <surface>
            <contact>
              <ode/>
            </contact>
            <friction>
              <ode/>
              <torsional>
                <ode/>
              </torsional>
            </friction>
            <bounce/>
          </surface>
          <max_contacts>10</max_contacts>
        </collision>
        <visual name='locobot/arm_cradle_link_visual'>
          <pose>0 0 0 0 -0 0</pose>
          <geometry>
            <mesh>
              <scale>0.001 0.001 0.001</scale>
              <uri>/home/bharat/catkin_ws/src/interbotix_ros_rovers/interbotix_ros_xslocobots/interbotix_xslocobot_descriptions/meshes/locobot_meshes/locobot_arm_cradle.stl</uri>
            </mesh>
          </geometry>
          <material>
            <script>
              <name>Custom/Interbotix</name>
              <uri>file://media/materials/scripts/gazebo.material</uri>
            </script>
          </material>
        </visual>
        <self_collide>0</self_collide>
        <enable_wind>0</enable_wind>
        <kinematic>0</kinematic>
      </link>
      <joint name='lidar_tower' type='revolute'>
        <pose relative_to='locobot/camera_tower_link'>-0.066095 0 0.402 0 -0 0</pose>
        <parent>locobot/camera_tower_link</parent>
        <child>locobot/lidar_tower_link</child>
        <axis>
          <limit>
            <lower>0</lower>
            <upper>0</upper>
          </limit>
          <dynamics>
            <damping>0</damping>
            <friction>0</friction>
            <spring_reference>0</spring_reference>
            <spring_stiffness>0</spring_stiffness>
          </dynamics>
          <xyz>0 0 1</xyz>
        </axis>
        <physics>
          <ode>
            <limit>
              <cfm>0</cfm>
              <erp>0.2</erp>
            </limit>
          </ode>
        </physics>
      </joint>
      <link name='locobot/lidar_tower_link'>
        <pose relative_to='lidar_tower'>0 0 0 0 -0 0</pose>
        <inertial>
          <pose>-0.007482 -2e-05 0.050796 0 -0 0</pose>
          <mass>0.155485</mass>
          <inertia>
            <ixx>0.0007642</ixx>
            <ixy>-1.357e-07</ixy>
            <ixz>1.347e-05</ixz>
            <iyy>0.0001285</iyy>
            <iyz>3.54e-08</iyz>
            <izz>0.000784</izz>
          </inertia>
        </inertial>
        <collision name='locobot/lidar_tower_link_collision'>
          <pose>0 0 0 0 -0 0</pose>
          <geometry>
            <mesh>
              <scale>0.001 0.001 0.001</scale>
              <uri>/home/bharat/catkin_ws/src/interbotix_ros_rovers/interbotix_ros_xslocobots/interbotix_xslocobot_descriptions/meshes/locobot_meshes/locobot_lidar_tower_simple.stl</uri>
            </mesh>
          </geometry>
          <surface>
            <contact>
              <ode/>
            </contact>
            <friction>
              <ode/>
              <torsional>
                <ode/>
              </torsional>
            </friction>
            <bounce/>
          </surface>
          <max_contacts>10</max_contacts>
        </collision>
        <visual name='locobot/lidar_tower_link_visual'>
          <pose>0 0 0 0 -0 0</pose>
          <geometry>
            <mesh>
              <scale>0.001 0.001 0.001</scale>
              <uri>/home/bharat/catkin_ws/src/interbotix_ros_rovers/interbotix_ros_xslocobots/interbotix_xslocobot_descriptions/meshes/locobot_meshes/locobot_lidar_tower.stl</uri>
            </mesh>
          </geometry>
          <material>
            <script>
              <name>Custom/Interbotix</name>
              <uri>file://media/materials/scripts/gazebo.material</uri>
            </script>
          </material>
        </visual>
        <self_collide>0</self_collide>
        <enable_wind>0</enable_wind>
        <kinematic>0</kinematic>
      </link>
      <joint name='lidar' type='revolute'>
        <pose relative_to='locobot/lidar_tower_link'>0 0 0.09425 0 -0 3.14159</pose>
        <parent>locobot/lidar_tower_link</parent>
        <child>locobot/laser_frame_link</child>
        <axis>
          <limit>
            <lower>0</lower>
            <upper>0</upper>
          </limit>
          <dynamics>
            <damping>0</damping>
            <friction>0</friction>
            <spring_reference>0</spring_reference>
            <spring_stiffness>0</spring_stiffness>
          </dynamics>
          <xyz>0 0 1</xyz>
        </axis>
        <physics>
          <ode>
            <limit>
              <cfm>0</cfm>
              <erp>0.2</erp>
            </limit>
          </ode>
        </physics>
      </joint>
      <link name='locobot/laser_frame_link'>
        <pose relative_to='lidar'>0 0 0 0 -0 0</pose>
        <inertial>
          <pose>0.000738 0 -0.010381 0 -0 0</pose>
          <mass>0.196</mass>
          <inertia>
            <ixx>9.075e-05</ixx>
            <ixy>1e-10</ixy>
            <ixz>-1.4234e-06</ixz>
            <iyy>8.776e-05</iyy>
            <iyz>0</iyz>
            <izz>0.0001268</izz>
          </inertia>
        </inertial>
        <collision name='locobot/laser_frame_link_collision'>
          <pose>0 0 -0.0091 0 -0 0</pose>
          <geometry>
            <cylinder>
              <length>0.0408</length>
              <radius>0.03785</radius>
            </cylinder>
          </geometry>
          <surface>
            <contact>
              <ode/>
            </contact>
            <friction>
              <ode/>
              <torsional>
                <ode/>
              </torsional>
            </friction>
            <bounce/>
          </surface>
          <max_contacts>10</max_contacts>
        </collision>
        <visual name='locobot/laser_frame_link_visual'>
          <pose>0 0 0 0 -0 0</pose>
          <geometry>
            <mesh>
              <scale>0.001 0.001 0.001</scale>
              <uri>/home/bharat/catkin_ws/src/interbotix_ros_rovers/interbotix_ros_xslocobots/interbotix_xslocobot_descriptions/meshes/locobot_meshes/locobot_lidar.stl</uri>
            </mesh>
          </geometry>
          <material>
            <script>
              <name>Custom/Interbotix</name>
              <uri>file://media/materials/scripts/gazebo.material</uri>
            </script>
          </material>
        </visual>
        <sensor name='rplidar' type='ray'>
          <pose>0 0 0 0 -0 0</pose>
          <visualize>0</visualize>
          <update_rate>30</update_rate>
          <ray>
            <scan>
              <horizontal>
                <samples>400</samples>
                <resolution>1</resolution>
                <min_angle>-3.14159</min_angle>
                <max_angle>3.14159</max_angle>
              </horizontal>
              <vertical>
                <samples>1</samples>
                <min_angle>0</min_angle>
                <max_angle>0</max_angle>
              </vertical>
            </scan>
            <range>
              <min>0.2</min>
              <max>16</max>
              <resolution>0.02</resolution>
            </range>
            <noise>
              <type>gaussian</type>
              <mean>0</mean>
              <stddev>0.01</stddev>
            </noise>
          </ray>
          <plugin name='gazebo_ros_head_rplidar_controller' filename='libgazebo_ros_laser.so'>
            <topicName>scan</topicName>
            <frameName>locobot/laser_frame_link</frameName>
            <robotNamespace>/locobot/</robotNamespace>
          </plugin>
        </sensor>
        <self_collide>0</self_collide>
        <enable_wind>0</enable_wind>
        <kinematic>0</kinematic>
      </link>
      <joint name='pan' type='revolute'>
        <pose relative_to='locobot/camera_tower_link'>0.061228 0 0.402 0 -0 0</pose>
        <parent>locobot/camera_tower_link</parent>
        <child>locobot/pan_link</child>
        <axis>
          <xyz>0 0 1</xyz>
          <limit>
            <lower>-1.5708</lower>
            <upper>1.5708</upper>
            <effort>2</effort>
            <velocity>3.14159</velocity>
          </limit>
          <dynamics>
            <spring_reference>0</spring_reference>
            <spring_stiffness>0</spring_stiffness>
          </dynamics>
        </axis>
      </joint>
      <link name='locobot/pan_link'>
        <pose relative_to='pan'>0 0 0 0 -0 0</pose>
        <inertial>
          <pose>0.012 0.000496 0.018504 0 -0 1.5708</pose>
          <mass>0.098997</mass>
          <inertia>
            <ixx>2.763e-05</ixx>
            <ixy>4.18e-08</ixy>
            <ixz>5.145e-07</ixz>
            <iyy>2.043e-05</iyy>
            <iyz>-4.21e-08</iyz>
            <izz>2.763e-05</izz>
          </inertia>
        </inertial>
        <collision name='locobot/pan_link_collision'>
          <pose>0 0 0 0 -0 1.5708</pose>
          <geometry>
            <mesh>
              <scale>0.001 0.001 0.001</scale>
              <uri>/home/bharat/catkin_ws/src/interbotix_ros_rovers/interbotix_ros_xslocobots/interbotix_xslocobot_descriptions/meshes/locobot_meshes/locobot_pan.stl</uri>
            </mesh>
          </geometry>
          <surface>
            <contact>
              <ode/>
            </contact>
            <friction>
              <ode/>
              <torsional>
                <ode/>
              </torsional>
            </friction>
            <bounce/>
          </surface>
          <max_contacts>10</max_contacts>
        </collision>
        <visual name='locobot/pan_link_visual'>
          <pose>0 0 0 0 -0 1.5708</pose>
          <geometry>
            <mesh>
              <scale>0.001 0.001 0.001</scale>
              <uri>/home/bharat/catkin_ws/src/interbotix_ros_rovers/interbotix_ros_xslocobots/interbotix_xslocobot_descriptions/meshes/locobot_meshes/locobot_pan.stl</uri>
            </mesh>
          </geometry>
          <material>
            <script>
              <name>Custom/Interbotix</name>
              <uri>file://media/materials/scripts/gazebo.material</uri>
            </script>
          </material>
        </visual>
        <self_collide>1</self_collide>
        <enable_wind>0</enable_wind>
        <kinematic>0</kinematic>
      </link>
      <joint name='tilt' type='revolute'>
        <pose relative_to='locobot/pan_link'>0.025034 0 0.019 0 -0 0</pose>
        <parent>locobot/pan_link</parent>
        <child>locobot/tilt_link</child>
        <axis>
          <xyz>0 1 0</xyz>
          <limit>
            <lower>-1.5708</lower>
            <upper>1.309</upper>
            <effort>2</effort>
            <velocity>3.14159</velocity>
          </limit>
          <dynamics>
            <spring_reference>0</spring_reference>
            <spring_stiffness>0</spring_stiffness>
          </dynamics>
        </axis>
      </joint>
      <link name='locobot/tilt_link'>
        <pose relative_to='tilt'>0 0 0 0 -0 0</pose>
        <inertial>
          <pose>0.023774 -2e-06 8e-06 0 -0 1.5708</pose>
          <mass>0.019845</mass>
          <inertia>
            <ixx>2.1677e-06</ixx>
            <ixy>0</ixy>
            <ixz>1e-10</ixz>
            <iyy>6.3634e-06</iyy>
            <iyz>3e-10</iyz>
            <izz>6.6157e-06</izz>
          </inertia>
        </inertial>
        <collision name='locobot/tilt_link_collision'>
          <pose>0 0 0 0 -0 1.5708</pose>
          <geometry>
            <mesh>
              <scale>0.001 0.001 0.001</scale>
              <uri>/home/bharat/catkin_ws/src/interbotix_ros_rovers/interbotix_ros_xslocobots/interbotix_xslocobot_descriptions/meshes/locobot_meshes/locobot_tilt.stl</uri>
            </mesh>
          </geometry>
          <surface>
            <contact>
              <ode/>
            </contact>
            <friction>
              <ode/>
              <torsional>
                <ode/>
              </torsional>
            </friction>
            <bounce/>
          </surface>
          <max_contacts>10</max_contacts>
        </collision>
        <visual name='locobot/tilt_link_visual'>
          <pose>0 0 0 0 -0 1.5708</pose>
          <geometry>
            <mesh>
              <scale>0.001 0.001 0.001</scale>
              <uri>/home/bharat/catkin_ws/src/interbotix_ros_rovers/interbotix_ros_xslocobots/interbotix_xslocobot_descriptions/meshes/locobot_meshes/locobot_tilt.stl</uri>
            </mesh>
          </geometry>
          <material>
            <script>
              <name>Custom/Interbotix</name>
              <uri>file://media/materials/scripts/gazebo.material</uri>
            </script>
          </material>
        </visual>
        <self_collide>1</self_collide>
        <enable_wind>0</enable_wind>
        <kinematic>0</kinematic>
      </link>
      <joint name='camera' type='revolute'>
        <pose relative_to='locobot/tilt_link'>0.05318 0.0175 9e-06 0 -0 0</pose>
        <parent>locobot/tilt_link</parent>
        <child>locobot/camera_link</child>
        <axis>
          <limit>
            <lower>0</lower>
            <upper>0</upper>
          </limit>
          <dynamics>
            <damping>0</damping>
            <friction>0</friction>
            <spring_reference>0</spring_reference>
            <spring_stiffness>0</spring_stiffness>
          </dynamics>
          <xyz>0 0 1</xyz>
        </axis>
        <physics>
          <ode>
            <limit>
              <cfm>0</cfm>
              <erp>0.2</erp>
            </limit>
          </ode>
        </physics>
      </joint>
      <link name='locobot/camera_link'>
        <pose relative_to='camera'>0 0 0 0 -0 0</pose>
        <inertial>
          <pose>-0.008972 -0.015818 3e-06 0 -0 0</pose>
          <mass>0.072</mass>
          <inertia>
            <ixx>4.654e-05</ixx>
            <ixy>3.028e-07</ixy>
            <ixz>2.45e-08</ixz>
            <iyy>6.9128e-06</iyy>
            <iyz>2.48e-08</iyz>
            <izz>4.686e-05</izz>
          </inertia>
        </inertial>
        <collision name='locobot/camera_link_collision'>
          <pose>0 0 0 0 -0 0</pose>
          <geometry>
            <mesh>
              <scale>0.001 0.001 0.001</scale>
              <uri>/home/bharat/catkin_ws/src/interbotix_ros_rovers/interbotix_ros_xslocobots/interbotix_xslocobot_descriptions/meshes/locobot_meshes/locobot_camera.stl</uri>
            </mesh>
          </geometry>
          <surface>
            <contact>
              <ode/>
            </contact>
            <friction>
              <ode/>
              <torsional>
                <ode/>
              </torsional>
            </friction>
            <bounce/>
          </surface>
          <max_contacts>10</max_contacts>
        </collision>
        <visual name='locobot/camera_link_visual'>
          <pose>0 0 0 0 -0 0</pose>
          <geometry>
            <mesh>
              <scale>0.001 0.001 0.001</scale>
              <uri>/home/bharat/catkin_ws/src/interbotix_ros_rovers/interbotix_ros_xslocobots/interbotix_xslocobot_descriptions/meshes/locobot_meshes/locobot_camera.stl</uri>
            </mesh>
          </geometry>
          <material>
            <script>
              <name>Gazebo/Grey</name>
              <uri>file://media/materials/scripts/gazebo.material</uri>
            </script>
          </material>
        </visual>
        <self_collide>1</self_collide>
        <sensor name='camera_frame_sensor' type='depth'>
          <always_on>1</always_on>
          <update_rate>30</update_rate>
          <camera>
            <horizontal_fov>0.994837</horizontal_fov>
            <image>
              <format>R8G8B8</format>
              <width>640</width>
              <height>480</height>
            </image>
            <clip>
              <near>0.01</near>
              <far>10</far>
            </clip>
          </camera>
          <plugin name='camera_frame_controller' filename='libgazebo_ros_openni_kinect.so'>
            <alwaysOn>1</alwaysOn>
            <updateRate>0.0</updateRate>
            <cameraName>camera</cameraName>
            <imageTopicName>color/image_raw</imageTopicName>
            <cameraInfoTopicName>color/camera_info</cameraInfoTopicName>
            <depthImageTopicName>aligned_depth_to_color/image_raw</depthImageTopicName>
            <depthImageCameraInfoTopicName>aligned_depth_to_color/camera_info</depthImageCameraInfoTopicName>
            <pointCloudTopicName>depth_registered/points</pointCloudTopicName>
            <frameName>locobot/camera_depth_link</frameName>
            <pointCloudCutoff>0.01</pointCloudCutoff>
            <pointCloudCutoffMax>10</pointCloudCutoffMax>
            <distortionK1>0.00000001</distortionK1>
            <distortionK2>0.00000001</distortionK2>
            <distortionK3>0.00000001</distortionK3>
            <distortionT1>0.00000001</distortionT1>
            <distortionT2>0.00000001</distortionT2>
            <CxPrime>0</CxPrime>
            <Cx>0</Cx>
            <Cy>0</Cy>
            <focalLength>0</focalLength>
            <hackBaseline>0</hackBaseline>
            <robotNamespace>/locobot/</robotNamespace>
          </plugin>
        </sensor>
        <enable_wind>0</enable_wind>
        <kinematic>0</kinematic>
      </link>
      <joint name='front_caster_joint' type='fixed'>
        <pose relative_to='locobot/base_footprint'>0.125 0 0.0122 -1.5708 0 0</pose>
        <parent>locobot/base_footprint</parent>
        <child>locobot/front_caster_link</child>
        <axis>
          <dynamics>
            <spring_reference>0</spring_reference>
            <spring_stiffness>0</spring_stiffness>
          </dynamics>
          <xyz>0 0 1</xyz>
          <limit>
            <lower>-1e+16</lower>
            <upper>1e+16</upper>
          </limit>
        </axis>
        <physics>
          <ode>
            <limit>
              <cfm>0</cfm>
              <erp>0.2</erp>
            </limit>
          </ode>
        </physics>
      </joint>
      <link name='locobot/front_caster_link'>
        <pose relative_to='front_caster_joint'>0 0 0 0 -0 0</pose>
        <inertial>
          <pose>0 0 0 0 -0 0</pose>
          <mass>0.01</mass>
          <inertia>
            <ixx>4e-07</ixx>
            <ixy>0</ixy>
            <ixz>0</ixz>
            <iyy>4e-07</iyy>
            <iyz>0</iyz>
            <izz>4e-07</izz>
          </inertia>
        </inertial>
        <collision name='locobot/front_caster_link_collision'>
          <pose>0 0 0 0 -0 0</pose>
          <geometry>
            <sphere>
              <radius>0.01</radius>
            </sphere>
          </geometry>
          <max_contacts>10</max_contacts>
          <surface>
            <contact>
              <ode/>
            </contact>
            <bounce/>
            <friction>
              <torsional>
                <ode/>
              </torsional>
              <ode/>
            </friction>
          </surface>
        </collision>
        <visual name='locobot/front_caster_link_visual'>
          <pose>0 0 0 0 -0 0</pose>
          <geometry>
            <sphere>
              <radius>0.01</radius>
            </sphere>
          </geometry>
        </visual>
        <self_collide>0</self_collide>
        <enable_wind>0</enable_wind>
        <kinematic>0</kinematic>
      </link>
      <joint name='locobot/mouse_joint' type='fixed'>
        <pose relative_to='locobot/base_footprint'>0.1015 0.087 0.0092 0 0 -0.785398</pose>
        <parent>locobot/base_footprint</parent>
        <child>locobot/mouse</child>
        <axis>
          <dynamics>
            <spring_reference>0</spring_reference>
            <spring_stiffness>0</spring_stiffness>
          </dynamics>
          <xyz>0 0 1</xyz>
          <limit>
            <lower>-1e+16</lower>
            <upper>1e+16</upper>
          </limit>
        </axis>
        <physics>
          <ode>
            <limit>
              <cfm>0</cfm>
              <erp>0.2</erp>
            </limit>
          </ode>
        </physics>
      </joint>
      <link name='locobot/mouse'>
        <pose relative_to='locobot/mouse_joint'>0 0 0 0 -0 0</pose>
        <inertial>
          <pose>0 0 0 0 -0 0</pose>
          <mass>0.01</mass>
          <inertia>
            <ixx>1.66667e-07</ixx>
            <ixy>0</ixy>
            <ixz>0</ixz>
            <iyy>1.66667e-07</iyy>
            <iyz>0</iyz>
            <izz>1.66667e-07</izz>
          </inertia>
        </inertial>
        <self_collide>0</self_collide>
        <enable_wind>0</enable_wind>
        <kinematic>0</kinematic>
      </link>
      <joint name='plate' type='revolute'>
        <pose relative_to='locobot/base_footprint'>0 0 0.0934 0 -0 0</pose>
        <parent>locobot/base_footprint</parent>
        <child>locobot/plate_link</child>
        <axis>
          <limit>
            <lower>0</lower>
            <upper>0</upper>
          </limit>
          <dynamics>
            <damping>0</damping>
            <friction>0</friction>
            <spring_reference>0</spring_reference>
            <spring_stiffness>0</spring_stiffness>
          </dynamics>
          <xyz>0 0 1</xyz>
        </axis>
        <physics>
          <ode>
            <limit>
              <cfm>0</cfm>
              <erp>0.2</erp>
            </limit>
          </ode>
        </physics>
      </joint>
      <link name='locobot/plate_link'>
        <pose relative_to='plate'>0 0 0 0 -0 0</pose>
        <inertial>
          <pose>0.007972 0 0.007857 0 -0 0</pose>
          <mass>0.941674</mass>
          <inertia>
            <ixx>0.00561463</ixx>
            <ixy>-2.9e-11</ixy>
            <ixz>-0.000250156</ixz>
            <iyy>0.00454001</iyy>
            <iyz>6.27e-10</iyz>
            <izz>0.0100314</izz>
          </inertia>
        </inertial>
        <collision name='locobot/plate_link_collision'>
          <pose>0 0 0 0 -0 0</pose>
          <geometry>
            <mesh>
              <scale>1 1 1</scale>
              <uri>/home/bharat/catkin_ws/src/interbotix_ros_rovers/interbotix_ros_xslocobots/interbotix_xslocobot_descriptions/meshes/locobot_meshes/create3_version/locobot_base_plate.stl</uri>
            </mesh>
          </geometry>
          <surface>
            <contact>
              <ode/>
            </contact>
            <friction>
              <ode/>
              <torsional>
                <ode/>
              </torsional>
            </friction>
            <bounce/>
          </surface>
          <max_contacts>10</max_contacts>
        </collision>
        <collision name='locobot/plate_link_fixed_joint_lump__locobot/arm_stand_link_collision_1'>
          <pose>0.092002 0 0.007763 0 -0 0</pose>
          <geometry>
            <mesh>
              <scale>1 1 1</scale>
              <uri>/home/bharat/catkin_ws/src/interbotix_ros_rovers/interbotix_ros_xslocobots/interbotix_xslocobot_descriptions/meshes/locobot_meshes/create3_version/locobot_arm_stand.stl</uri>
            </mesh>
          </geometry>
          <max_contacts>10</max_contacts>
          <surface>
            <contact>
              <ode/>
            </contact>
            <bounce/>
            <friction>
              <torsional>
                <ode/>
              </torsional>
              <ode/>
            </friction>
          </surface>
        </collision>
        <visual name='locobot/plate_link_visual'>
          <pose>0 0 0 0 -0 0</pose>
          <geometry>
            <mesh>
              <scale>1 1 1</scale>
              <uri>/home/bharat/catkin_ws/src/interbotix_ros_rovers/interbotix_ros_xslocobots/interbotix_xslocobot_descriptions/meshes/locobot_meshes/create3_version/locobot_base_plate.stl</uri>
            </mesh>
          </geometry>
          <material>
            <script>
              <name>Custom/Interbotix</name>
              <uri>file://media/materials/scripts/gazebo.material</uri>
            </script>
          </material>
        </visual>
        <visual name='locobot/plate_link_fixed_joint_lump__locobot/arm_stand_link_visual_1'>
          <pose>0.092002 0 0.007763 0 -0 0</pose>
          <geometry>
            <mesh>
              <scale>1 1 1</scale>
              <uri>/home/bharat/catkin_ws/src/interbotix_ros_rovers/interbotix_ros_xslocobots/interbotix_xslocobot_descriptions/meshes/locobot_meshes/create3_version/locobot_arm_stand.stl</uri>
            </mesh>
          </geometry>
        </visual>
        <self_collide>0</self_collide>
        <enable_wind>0</enable_wind>
        <kinematic>0</kinematic>
      </link>
      <joint name='arm_base_link_joint' type='revolute'>
        <pose relative_to='locobot/plate_link'>0.092002 0 0.030763 0 -0 0</pose>
        <parent>locobot/plate_link</parent>
        <child>locobot/arm_base_link</child>
        <axis>
          <limit>
            <lower>0</lower>
            <upper>0</upper>
          </limit>
          <dynamics>
            <damping>0</damping>
            <friction>0</friction>
            <spring_reference>0</spring_reference>
            <spring_stiffness>0</spring_stiffness>
          </dynamics>
          <xyz>0 0 1</xyz>
        </axis>
        <physics>
          <ode>
            <limit>
              <cfm>0</cfm>
              <erp>0.2</erp>
            </limit>
          </ode>
        </physics>
      </joint>
      <link name='locobot/arm_base_link'>
        <pose relative_to='arm_base_link_joint'>0 0 0 0 -0 0</pose>
        <inertial>
          <pose>-0.000135 -2.7e-05 0.033876 1.5708 -0 1.5708</pose>
          <mass>0.379673</mass>
          <inertia>
            <ixx>0.0004351</ixx>
            <ixy>7.07e-08</ixy>
            <ixz>2.66e-08</ixz>
            <iyy>0.0004452</iyy>
            <iyz>-2.2881e-06</iyz>
            <izz>0.0005731</izz>
          </inertia>
        </inertial>
        <collision name='locobot/arm_base_link_collision'>
          <pose>-0.095773 0 -0.10565 1.5708 -0 1.5708</pose>
          <geometry>
            <mesh>
              <scale>0.001 0.001 0.001</scale>
              <uri>/home/bharat/catkin_ws/src/interbotix_ros_rovers/interbotix_ros_xslocobots/interbotix_xslocobot_descriptions/meshes/mobile_wx200_meshes/mobile_wx200_1_base.stl</uri>
            </mesh>
          </geometry>
          <surface>
            <contact>
              <ode/>
            </contact>
            <friction>
              <ode/>
              <torsional>
                <ode/>
              </torsional>
            </friction>
            <bounce/>
          </surface>
          <max_contacts>10</max_contacts>
        </collision>
        <visual name='locobot/arm_base_link_visual'>
          <pose>-0.095773 0 -0.10565 1.5708 -0 1.5708</pose>
          <geometry>
            <mesh>
              <scale>0.001 0.001 0.001</scale>
              <uri>/home/bharat/catkin_ws/src/interbotix_ros_rovers/interbotix_ros_xslocobots/interbotix_xslocobot_descriptions/meshes/mobile_wx200_meshes/mobile_wx200_1_base.stl</uri>
            </mesh>
          </geometry>
          <material>
            <script>
              <name>Custom/Interbotix</name>
              <uri>file://media/materials/scripts/gazebo.material</uri>
            </script>
          </material>
        </visual>
        <velocity_decay>
          <linear>0.01</linear>
          <angular>0.01</angular>
        </velocity_decay>
        <self_collide>0</self_collide>
        <enable_wind>0</enable_wind>
        <kinematic>0</kinematic>
      </link>
      <joint name='waist' type='revolute'>
        <pose relative_to='locobot/arm_base_link'>0 0 0.066175 0 -0 0</pose>
        <parent>locobot/arm_base_link</parent>
        <child>locobot/shoulder_link</child>
        <axis>
          <xyz>0 0 1</xyz>
          <limit>
            <lower>-3.14158</lower>
            <upper>3.14158</upper>
            <effort>8</effort>
            <velocity>3.14159</velocity>
          </limit>
          <dynamics>
            <damping>0</damping>
            <friction>0.1</friction>
            <spring_reference>0</spring_reference>
            <spring_stiffness>0</spring_stiffness>
          </dynamics>
        </axis>
      </joint>
      <link name='locobot/shoulder_link'>
        <pose relative_to='waist'>0 0 0 0 -0 0</pose>
        <inertial>
          <pose>2.2e-05 4.1e-05 0.006629 0 -0 1.5708</pose>
          <mass>0.480879</mass>
          <inertia>
            <ixx>0.000379</ixx>
            <ixy>2.2e-09</ixy>
            <ixz>-3.561e-07</ixz>
            <iyy>0.0005557</iyy>
            <iyz>1.2247e-06</iyz>
            <izz>0.0005889</izz>
          </inertia>
        </inertial>
        <collision name='locobot/shoulder_link_collision'>
          <pose>0 0 -0.003 0 -0 1.5708</pose>
          <geometry>
            <mesh>
              <scale>0.001 0.001 0.001</scale>
              <uri>/home/bharat/catkin_ws/src/interbotix_ros_rovers/interbotix_ros_xslocobots/interbotix_xslocobot_descriptions/meshes/mobile_wx200_meshes/mobile_wx200_2_shoulder.stl</uri>
            </mesh>
          </geometry>
          <surface>
            <contact>
              <ode/>
            </contact>
            <friction>
              <ode/>
              <torsional>
                <ode/>
              </torsional>
            </friction>
            <bounce/>
          </surface>
          <max_contacts>10</max_contacts>
        </collision>
        <visual name='locobot/shoulder_link_visual'>
          <pose>0 0 -0.003 0 -0 1.5708</pose>
          <geometry>
            <mesh>
              <scale>0.001 0.001 0.001</scale>
              <uri>/home/bharat/catkin_ws/src/interbotix_ros_rovers/interbotix_ros_xslocobots/interbotix_xslocobot_descriptions/meshes/mobile_wx200_meshes/mobile_wx200_2_shoulder.stl</uri>
            </mesh>
          </geometry>
          <material>
            <script>
              <name>Custom/Interbotix</name>
              <uri>file://media/materials/scripts/gazebo.material</uri>
            </script>
          </material>
        </visual>
        <velocity_decay>
          <linear>0.01</linear>
          <angular>0.01</angular>
        </velocity_decay>
        <self_collide>1</self_collide>
        <enable_wind>0</enable_wind>
        <kinematic>0</kinematic>
      </link>
      <joint name='shoulder' type='revolute'>
        <pose relative_to='locobot/shoulder_link'>0 0 0.03865 0 -0 0</pose>
        <parent>locobot/shoulder_link</parent>
        <child>locobot/upper_arm_link</child>
        <axis>
          <xyz>0 1 0</xyz>
          <limit>
            <lower>-1.88496</lower>
            <upper>1.97222</upper>
            <effort>18</effort>
            <velocity>3.14159</velocity>
          </limit>
          <dynamics>
            <damping>0</damping>
            <friction>0.1</friction>
            <spring_reference>0</spring_reference>
            <spring_stiffness>0</spring_stiffness>
          </dynamics>
        </axis>
      </joint>
      <link name='locobot/upper_arm_link'>
        <pose relative_to='shoulder'>0 0 0 0 -0 0</pose>
        <inertial>
          <pose>0.011971 -0.000118 0.139429 0 -0 1.5708</pose>
          <mass>0.297781</mass>
          <inertia>
            <ixx>0.00171</ixx>
            <ixy>-1.1433e-06</ixy>
            <ixz>2.1161e-06</ixz>
            <iyy>0.001631</iyy>
            <iyz>0.0002135</iyz>
            <izz>0.0001482</izz>
          </inertia>
        </inertial>
        <collision name='locobot/upper_arm_link_collision'>
          <pose>0 0 0 0 -0 1.5708</pose>
          <geometry>
            <mesh>
              <scale>0.001 0.001 0.001</scale>
              <uri>/home/bharat/catkin_ws/src/interbotix_ros_rovers/interbotix_ros_xslocobots/interbotix_xslocobot_descriptions/meshes/mobile_wx200_meshes/mobile_wx200_3_upper_arm.stl</uri>
            </mesh>
          </geometry>
          <surface>
            <contact>
              <ode/>
            </contact>
            <friction>
              <ode/>
              <torsional>
                <ode/>
              </torsional>
            </friction>
            <bounce/>
          </surface>
          <max_contacts>10</max_contacts>
        </collision>
        <visual name='locobot/upper_arm_link_visual'>
          <pose>0 0 0 0 -0 1.5708</pose>
          <geometry>
            <mesh>
              <scale>0.001 0.001 0.001</scale>
              <uri>/home/bharat/catkin_ws/src/interbotix_ros_rovers/interbotix_ros_xslocobots/interbotix_xslocobot_descriptions/meshes/mobile_wx200_meshes/mobile_wx200_3_upper_arm.stl</uri>
            </mesh>
          </geometry>
          <material>
            <script>
              <name>Custom/Interbotix</name>
              <uri>file://media/materials/scripts/gazebo.material</uri>
            </script>
          </material>
        </visual>
        <velocity_decay>
          <linear>0.01</linear>
          <angular>0.01</angular>
        </velocity_decay>
        <self_collide>1</self_collide>
        <enable_wind>0</enable_wind>
        <kinematic>0</kinematic>
      </link>
      <joint name='elbow' type='revolute'>
        <pose relative_to='locobot/upper_arm_link'>0.05 0 0.2 0 -0 0</pose>
        <parent>locobot/upper_arm_link</parent>
        <child>locobot/forearm_link</child>
        <axis>
          <xyz>0 1 0</xyz>
          <limit>
            <lower>-1.88496</lower>
            <upper>1.62316</upper>
            <effort>13</effort>
            <velocity>3.14159</velocity>
          </limit>
          <dynamics>
            <damping>0</damping>
            <friction>0.1</friction>
            <spring_reference>0</spring_reference>
            <spring_stiffness>0</spring_stiffness>
          </dynamics>
        </axis>
      </joint>
      <link name='locobot/forearm_link'>
        <pose relative_to='elbow'>0 0 0 0 -0 0</pose>
        <inertial>
          <pose>0.121192 -0.000124 0 0 -0 1.5708</pose>
          <mass>0.283651</mass>
          <inertia>
            <ixx>0.001185</ixx>
            <ixy>-2.4317e-06</ixy>
            <ixz>0</ixz>
            <iyy>6.829e-05</iyy>
            <iyz>0</iyz>
            <izz>0.001206</izz>
          </inertia>
        </inertial>
        <collision name='locobot/forearm_link_collision'>
          <pose>0 0 0 0 -0 1.5708</pose>
          <geometry>
            <mesh>
              <scale>0.001 0.001 0.001</scale>
              <uri>/home/bharat/catkin_ws/src/interbotix_ros_rovers/interbotix_ros_xslocobots/interbotix_xslocobot_descriptions/meshes/mobile_wx200_meshes/mobile_wx200_4_forearm.stl</uri>
            </mesh>
          </geometry>
          <surface>
            <contact>
              <ode/>
            </contact>
            <friction>
              <ode/>
              <torsional>
                <ode/>
              </torsional>
            </friction>
            <bounce/>
          </surface>
          <max_contacts>10</max_contacts>
        </collision>
        <visual name='locobot/forearm_link_visual'>
          <pose>0 0 0 0 -0 1.5708</pose>
          <geometry>
            <mesh>
              <scale>0.001 0.001 0.001</scale>
              <uri>/home/bharat/catkin_ws/src/interbotix_ros_rovers/interbotix_ros_xslocobots/interbotix_xslocobot_descriptions/meshes/mobile_wx200_meshes/mobile_wx200_4_forearm.stl</uri>
            </mesh>
          </geometry>
          <material>
            <script>
              <name>Custom/Interbotix</name>
              <uri>file://media/materials/scripts/gazebo.material</uri>
            </script>
          </material>
        </visual>
        <velocity_decay>
          <linear>0.01</linear>
          <angular>0.01</angular>
        </velocity_decay>
        <self_collide>1</self_collide>
        <enable_wind>0</enable_wind>
        <kinematic>0</kinematic>
      </link>
      <joint name='wrist_angle' type='revolute'>
        <pose relative_to='locobot/forearm_link'>0.2 0 0 0 -0 0</pose>
        <parent>locobot/forearm_link</parent>
        <child>locobot/wrist_link</child>
        <axis>
          <xyz>0 1 0</xyz>
          <limit>
            <lower>-1.74533</lower>
            <upper>2.14675</upper>
            <effort>5</effort>
            <velocity>3.14159</velocity>
          </limit>
          <dynamics>
            <damping>0</damping>
            <friction>0.1</friction>
            <spring_reference>0</spring_reference>
            <spring_stiffness>0</spring_stiffness>
          </dynamics>
        </axis>
      </joint>
      <link name='locobot/wrist_link'>
        <pose relative_to='wrist_angle'>0 0 0 0 -0 0</pose>
        <inertial>
          <pose>0.04236 -1.1e-05 0.010577 0 -0 1.5708</pose>
          <mass>0.084957</mass>
          <inertia>
            <ixx>3.082e-05</ixx>
            <ixy>1.91e-08</ixy>
            <ixz>2.3e-09</ixz>
            <iyy>2.822e-05</iyy>
            <iyz>2.5481e-06</iyz>
            <izz>3.152e-05</izz>
          </inertia>
        </inertial>
        <collision name='locobot/wrist_link_collision'>
          <pose>0 0 0 0 -0 1.5708</pose>
          <geometry>
            <mesh>
              <scale>0.001 0.001 0.001</scale>
              <uri>/home/bharat/catkin_ws/src/interbotix_ros_rovers/interbotix_ros_xslocobots/interbotix_xslocobot_descriptions/meshes/mobile_wx200_meshes/mobile_wx200_5_wrist.stl</uri>
            </mesh>
          </geometry>
          <surface>
            <contact>
              <ode/>
            </contact>
            <friction>
              <ode/>
              <torsional>
                <ode/>
              </torsional>
            </friction>
            <bounce/>
          </surface>
          <max_contacts>10</max_contacts>
        </collision>
        <visual name='locobot/wrist_link_visual'>
          <pose>0 0 0 0 -0 1.5708</pose>
          <geometry>
            <mesh>
              <scale>0.001 0.001 0.001</scale>
              <uri>/home/bharat/catkin_ws/src/interbotix_ros_rovers/interbotix_ros_xslocobots/interbotix_xslocobot_descriptions/meshes/mobile_wx200_meshes/mobile_wx200_5_wrist.stl</uri>
            </mesh>
          </geometry>
          <material>
            <script>
              <name>Custom/Interbotix</name>
              <uri>file://media/materials/scripts/gazebo.material</uri>
            </script>
          </material>
        </visual>
        <velocity_decay>
          <linear>0.01</linear>
          <angular>0.01</angular>
        </velocity_decay>
        <self_collide>1</self_collide>
        <enable_wind>0</enable_wind>
        <kinematic>0</kinematic>
      </link>
      <joint name='wrist_rotate' type='revolute'>
        <pose relative_to='locobot/wrist_link'>0.065 0 0 0 -0 0</pose>
        <parent>locobot/wrist_link</parent>
        <child>locobot/gripper_link</child>
        <axis>
          <xyz>1 0 0</xyz>
          <limit>
            <lower>-3.14158</lower>
            <upper>3.14158</upper>
            <effort>1</effort>
            <velocity>3.14159</velocity>
          </limit>
          <dynamics>
            <damping>0</damping>
            <friction>0.1</friction>
            <spring_reference>0</spring_reference>
            <spring_stiffness>0</spring_stiffness>
          </dynamics>
        </axis>
      </joint>
      <link name='locobot/gripper_link'>
        <pose relative_to='wrist_rotate'>0 0 0 0 -0 0</pose>
        <inertial>
          <pose>0.021631 0 0.01141 0 -0 1.5708</pose>
          <mass>0.072885</mass>
          <inertia>
            <ixx>2.537e-05</ixx>
            <ixy>0</ixy>
            <ixz>0</ixz>
            <iyy>1.836e-05</iyy>
            <iyz>4.34e-07</iyz>
            <izz>1.674e-05</izz>
          </inertia>
        </inertial>
        <collision name='locobot/gripper_link_collision'>
          <pose>-0.02 0 0 0 -0 1.5708</pose>
          <geometry>
            <mesh>
              <scale>0.001 0.001 0.001</scale>
              <uri>/home/bharat/catkin_ws/src/interbotix_ros_rovers/interbotix_ros_xslocobots/interbotix_xslocobot_descriptions/meshes/mobile_wx200_meshes/mobile_wx200_6_gripper.stl</uri>
            </mesh>
          </geometry>
          <surface>
            <contact>
              <ode/>
            </contact>
            <friction>
              <ode/>
              <torsional>
                <ode/>
              </torsional>
            </friction>
            <bounce/>
          </surface>
          <max_contacts>10</max_contacts>
        </collision>
        <visual name='locobot/gripper_link_visual'>
          <pose>-0.02 0 0 0 -0 1.5708</pose>
          <geometry>
            <mesh>
              <scale>0.001 0.001 0.001</scale>
              <uri>/home/bharat/catkin_ws/src/interbotix_ros_rovers/interbotix_ros_xslocobots/interbotix_xslocobot_descriptions/meshes/mobile_wx200_meshes/mobile_wx200_6_gripper.stl</uri>
            </mesh>
          </geometry>
          <material>
            <script>
              <name>Custom/Interbotix</name>
              <uri>file://media/materials/scripts/gazebo.material</uri>
            </script>
          </material>
        </visual>
        <velocity_decay>
          <linear>0.01</linear>
          <angular>0.01</angular>
        </velocity_decay>
        <self_collide>0</self_collide>
        <enable_wind>0</enable_wind>
        <kinematic>0</kinematic>
      </link>
      <joint name='ee_arm' type='revolute'>
        <pose relative_to='locobot/gripper_link'>0.043 0 0 0 -0 0</pose>
        <parent>locobot/gripper_link</parent>
        <child>locobot/ee_arm_link</child>
        <axis>
          <limit>
            <lower>0</lower>
            <upper>0</upper>
          </limit>
          <dynamics>
            <damping>0</damping>
            <friction>0</friction>
            <spring_reference>0</spring_reference>
            <spring_stiffness>0</spring_stiffness>
          </dynamics>
          <xyz>0 0 1</xyz>
        </axis>
        <physics>
          <ode>
            <limit>
              <cfm>0</cfm>
              <erp>0.2</erp>
            </limit>
          </ode>
        </physics>
      </joint>
      <link name='locobot/ee_arm_link'>
        <pose relative_to='ee_arm'>0 0 0 0 -0 0</pose>
        <inertial>
          <pose>0 0 0 0 -0 0</pose>
          <mass>0.001</mass>
          <inertia>
            <ixx>0.001</ixx>
            <ixy>0</ixy>
            <ixz>0</ixz>
            <iyy>0.001</iyy>
            <iyz>0</iyz>
            <izz>0.001</izz>
          </inertia>
        </inertial>
        <self_collide>0</self_collide>
        <enable_wind>0</enable_wind>
        <kinematic>0</kinematic>
      </link>
      <joint name='ar_tag' type='revolute'>
        <pose relative_to='locobot/ee_arm_link'>-0.017 0 0.04155 0 -0 0</pose>
        <parent>locobot/ee_arm_link</parent>
        <child>locobot/ar_tag_link</child>
        <axis>
          <limit>
            <lower>0</lower>
            <upper>0</upper>
          </limit>
          <dynamics>
            <damping>0</damping>
            <friction>0</friction>
            <spring_reference>0</spring_reference>
            <spring_stiffness>0</spring_stiffness>
          </dynamics>
          <xyz>0 0 1</xyz>
        </axis>
        <physics>
          <ode>
            <limit>
              <cfm>0</cfm>
              <erp>0.2</erp>
            </limit>
          </ode>
        </physics>
      </joint>
      <link name='locobot/ar_tag_link'>
        <pose relative_to='ar_tag'>0 0 0 0 -0 0</pose>
        <inertial>
          <pose>0 0 -0.00315 0 -0 0</pose>
          <mass>0.016507</mass>
          <inertia>
            <ixx>3.084e-06</ixx>
            <ixy>0</ixy>
            <ixz>0</ixz>
            <iyy>3.084e-06</iyy>
            <iyz>0</iyz>
            <izz>6.059e-06</izz>
          </inertia>
        </inertial>
        <collision name='locobot/ar_tag_link_collision'>
          <pose>0 0 0 0 -0 0</pose>
          <geometry>
            <mesh>
              <scale>0.001 0.001 0.001</scale>
              <uri>/home/bharat/catkin_ws/src/interbotix_ros_rovers/interbotix_ros_xslocobots/interbotix_xslocobot_descriptions/meshes/mobile_wx200_meshes/mobile_wx200_10_ar_tag.stl</uri>
            </mesh>
          </geometry>
          <surface>
            <contact>
              <ode/>
            </contact>
            <friction>
              <ode/>
              <torsional>
                <ode/>
              </torsional>
            </friction>
            <bounce/>
          </surface>
          <max_contacts>10</max_contacts>
        </collision>
        <visual name='locobot/ar_tag_link_visual'>
          <pose>0 0 0 0 -0 0</pose>
          <geometry>
            <mesh>
              <scale>0.001 0.001 0.001</scale>
              <uri>/home/bharat/catkin_ws/src/interbotix_ros_rovers/interbotix_ros_xslocobots/interbotix_xslocobot_descriptions/meshes/mobile_wx200_meshes/mobile_wx200_10_ar_tag.stl</uri>
            </mesh>
          </geometry>
          <material>
            <script>
              <name>Custom/Interbotix</name>
              <uri>file://media/materials/scripts/gazebo.material</uri>
            </script>
          </material>
        </visual>
        <self_collide>0</self_collide>
        <enable_wind>0</enable_wind>
        <kinematic>0</kinematic>
      </link>
      <joint name='gripper' type='revolute'>
        <pose relative_to='locobot/ee_arm_link'>0.0055 0 0 0 -0 0</pose>
        <parent>locobot/ee_arm_link</parent>
        <child>locobot/gripper_prop_link</child>
        <axis>
          <xyz>1 0 0</xyz>
          <limit>
            <effort>1</effort>
            <velocity>3.14159</velocity>
            <lower>-1e+16</lower>
            <upper>1e+16</upper>
          </limit>
          <dynamics>
            <damping>0</damping>
            <friction>0.1</friction>
            <spring_reference>0</spring_reference>
            <spring_stiffness>0</spring_stiffness>
          </dynamics>
        </axis>
      </joint>
      <link name='locobot/gripper_prop_link'>
        <pose relative_to='gripper'>0 0 0 0 -0 0</pose>
        <inertial>
          <pose>0.000846 -2e-06 4.2e-05 0 -0 1.5708</pose>
          <mass>0.00434</mass>
          <inertia>
            <ixx>5.923e-07</ixx>
            <ixy>0</ixy>
            <ixz>3.195e-07</ixz>
            <iyy>1.1156e-06</iyy>
            <iyz>-4e-10</iyz>
            <izz>5.743e-07</izz>
          </inertia>
        </inertial>
        <collision name='locobot/gripper_prop_link_collision'>
          <pose>-0.0685 0 0 0 -0 1.5708</pose>
          <geometry>
            <mesh>
              <scale>0.001 0.001 0.001</scale>
              <uri>/home/bharat/catkin_ws/src/interbotix_ros_rovers/interbotix_ros_xslocobots/interbotix_xslocobot_descriptions/meshes/mobile_wx200_meshes/mobile_wx200_7_gripper_prop.stl</uri>
            </mesh>
          </geometry>
          <surface>
            <contact>
              <ode/>
            </contact>
            <friction>
              <ode/>
              <torsional>
                <ode/>
              </torsional>
            </friction>
            <bounce/>
          </surface>
          <max_contacts>10</max_contacts>
        </collision>
        <visual name='locobot/gripper_prop_link_visual'>
          <pose>-0.0685 0 0 0 -0 1.5708</pose>
          <geometry>
            <mesh>
              <scale>0.001 0.001 0.001</scale>
              <uri>/home/bharat/catkin_ws/src/interbotix_ros_rovers/interbotix_ros_xslocobots/interbotix_xslocobot_descriptions/meshes/mobile_wx200_meshes/mobile_wx200_7_gripper_prop.stl</uri>
            </mesh>
          </geometry>
          <material>
            <script>
              <name>Custom/Interbotix</name>
              <uri>file://media/materials/scripts/gazebo.material</uri>
            </script>
          </material>
        </visual>
        <velocity_decay>
          <linear>0.01</linear>
          <angular>0.01</angular>
        </velocity_decay>
        <self_collide>0</self_collide>
        <enable_wind>0</enable_wind>
        <kinematic>0</kinematic>
      </link>
      <joint name='gripper_bar' type='revolute'>
        <pose relative_to='locobot/ee_arm_link'>0 0 0 0 -0 0</pose>
        <parent>locobot/ee_arm_link</parent>
        <child>locobot/gripper_bar_link</child>
        <axis>
          <limit>
            <lower>0</lower>
            <upper>0</upper>
          </limit>
          <dynamics>
            <damping>0</damping>
            <friction>0</friction>
            <spring_reference>0</spring_reference>
            <spring_stiffness>0</spring_stiffness>
          </dynamics>
          <xyz>0 0 1</xyz>
        </axis>
        <physics>
          <ode>
            <limit>
              <cfm>0</cfm>
              <erp>0.2</erp>
            </limit>
          </ode>
        </physics>
      </joint>
      <link name='locobot/gripper_bar_link'>
        <pose relative_to='gripper_bar'>0 0 0 0 -0 0</pose>
        <inertial>
          <pose>0.009687 1e-06 0.004962 0 -0 1.5708</pose>
          <mass>0.034199</mass>
          <inertia>
            <ixx>7.4125e-06</ixx>
            <ixy>-8e-10</ixy>
            <ixz>-6e-10</ixz>
            <iyy>2.843e-05</iyy>
            <iyz>-1.3889e-06</iyz>
            <izz>2.86e-05</izz>
          </inertia>
        </inertial>
        <collision name='locobot/gripper_bar_link_collision'>
          <pose>-0.063 0 0 0 -0 1.5708</pose>
          <geometry>
            <mesh>
              <scale>0.001 0.001 0.001</scale>
              <uri>/home/bharat/catkin_ws/src/interbotix_ros_rovers/interbotix_ros_xslocobots/interbotix_xslocobot_descriptions/meshes/mobile_wx200_meshes/mobile_wx200_8_gripper_bar.stl</uri>
            </mesh>
          </geometry>
          <surface>
            <contact>
              <ode/>
            </contact>
            <friction>
              <ode/>
              <torsional>
                <ode/>
              </torsional>
            </friction>
            <bounce/>
          </surface>
          <max_contacts>10</max_contacts>
        </collision>
        <visual name='locobot/gripper_bar_link_visual'>
          <pose>-0.063 0 0 0 -0 1.5708</pose>
          <geometry>
            <mesh>
              <scale>0.001 0.001 0.001</scale>
              <uri>/home/bharat/catkin_ws/src/interbotix_ros_rovers/interbotix_ros_xslocobots/interbotix_xslocobot_descriptions/meshes/mobile_wx200_meshes/mobile_wx200_8_gripper_bar.stl</uri>
            </mesh>
          </geometry>
          <material>
            <script>
              <name>Custom/Interbotix</name>
              <uri>file://media/materials/scripts/gazebo.material</uri>
            </script>
          </material>
        </visual>
        <self_collide>0</self_collide>
        <enable_wind>0</enable_wind>
        <kinematic>0</kinematic>
      </link>
      <joint name='ee_bar' type='revolute'>
        <pose relative_to='locobot/gripper_bar_link'>0.023 0 0 0 -0 0</pose>
        <parent>locobot/gripper_bar_link</parent>
        <child>locobot/fingers_link</child>
        <axis>
          <limit>
            <lower>0</lower>
            <upper>0</upper>
          </limit>
          <dynamics>
            <damping>0</damping>
            <friction>0</friction>
            <spring_reference>0</spring_reference>
            <spring_stiffness>0</spring_stiffness>
          </dynamics>
          <xyz>0 0 1</xyz>
        </axis>
        <physics>
          <ode>
            <limit>
              <cfm>0</cfm>
              <erp>0.2</erp>
            </limit>
          </ode>
        </physics>
      </joint>
      <link name='locobot/fingers_link'>
        <pose relative_to='ee_bar'>0 0 0 0 -0 0</pose>
        <inertial>
          <pose>0 0 0 0 -0 0</pose>
          <mass>0.001</mass>
          <inertia>
            <ixx>0.001</ixx>
            <ixy>0</ixy>
            <ixz>0</ixz>
            <iyy>0.001</iyy>
            <iyz>0</iyz>
            <izz>0.001</izz>
          </inertia>
        </inertial>
        <self_collide>0</self_collide>
        <enable_wind>0</enable_wind>
        <kinematic>0</kinematic>
      </link>
      <joint name='ee_gripper' type='revolute'>
        <pose relative_to='locobot/fingers_link'>0.027575 0 0 0 -0 0</pose>
        <parent>locobot/fingers_link</parent>
        <child>locobot/ee_gripper_link</child>
        <axis>
          <limit>
            <lower>0</lower>
            <upper>0</upper>
          </limit>
          <dynamics>
            <damping>0</damping>
            <friction>0</friction>
            <spring_reference>0</spring_reference>
            <spring_stiffness>0</spring_stiffness>
          </dynamics>
          <xyz>0 0 1</xyz>
        </axis>
        <physics>
          <ode>
            <limit>
              <cfm>0</cfm>
              <erp>0.2</erp>
            </limit>
          </ode>
        </physics>
      </joint>
      <link name='locobot/ee_gripper_link'>
        <pose relative_to='ee_gripper'>0 0 0 0 -0 0</pose>
        <inertial>
          <pose>0 0 0 0 -0 0</pose>
          <mass>0.001</mass>
          <inertia>
            <ixx>0.001</ixx>
            <ixy>0</ixy>
            <ixz>0</ixz>
            <iyy>0.001</iyy>
            <iyz>0</iyz>
            <izz>0.001</izz>
          </inertia>
        </inertial>
        <self_collide>0</self_collide>
        <enable_wind>0</enable_wind>
        <kinematic>0</kinematic>
      </link>
      <joint name='left_finger' type='prismatic'>
        <pose relative_to='locobot/fingers_link'>0 0 0 0 -0 0</pose>
        <parent>locobot/fingers_link</parent>
        <child>locobot/left_finger_link</child>
        <axis>
          <xyz>0 1 0</xyz>
          <limit>
            <lower>0.015</lower>
            <upper>0.037</upper>
            <effort>5</effort>
            <velocity>1</velocity>
          </limit>
          <dynamics>
            <damping>0</damping>
            <friction>0.1</friction>
            <spring_reference>0</spring_reference>
            <spring_stiffness>0</spring_stiffness>
          </dynamics>
        </axis>
      </joint>
      <link name='locobot/left_finger_link'>
        <pose relative_to='left_finger'>0 0 0 0 -0 0</pose>
        <inertial>
          <pose>0.013816 0 0 0 0 -1.5708</pose>
          <mass>0.016246</mass>
          <inertia>
            <ixx>4.731e-06</ixx>
            <ixy>-4.56e-07</ixy>
            <ixz>0</ixz>
            <iyy>1.5506e-06</iyy>
            <iyz>0</iyz>
            <izz>3.7467e-06</izz>
          </inertia>
        </inertial>
        <collision name='locobot/left_finger_link_collision'>
          <pose>0 0.005 0 0 -0 3.14159</pose>
          <geometry>
            <mesh>
              <scale>0.001 0.001 0.001</scale>
              <uri>/home/bharat/catkin_ws/src/interbotix_ros_rovers/interbotix_ros_xslocobots/interbotix_xslocobot_descriptions/meshes/mobile_wx200_meshes/mobile_wx200_9_gripper_finger.stl</uri>
            </mesh>
          </geometry>
          <surface>
            <contact>
              <ode/>
            </contact>
            <friction>
              <ode/>
              <torsional>
                <ode/>
              </torsional>
            </friction>
            <bounce/>
          </surface>
          <max_contacts>10</max_contacts>
        </collision>
        <visual name='locobot/left_finger_link_visual'>
          <pose>0 0.005 0 0 -0 3.14159</pose>
          <geometry>
            <mesh>
              <scale>0.001 0.001 0.001</scale>
              <uri>/home/bharat/catkin_ws/src/interbotix_ros_rovers/interbotix_ros_xslocobots/interbotix_xslocobot_descriptions/meshes/mobile_wx200_meshes/mobile_wx200_9_gripper_finger.stl</uri>
            </mesh>
          </geometry>
          <material>
            <script>
              <name>Custom/Interbotix</name>
              <uri>file://media/materials/scripts/gazebo.material</uri>
            </script>
          </material>
        </visual>
        <velocity_decay>
          <linear>0.01</linear>
          <angular>0.01</angular>
        </velocity_decay>
        <self_collide>0</self_collide>
        <enable_wind>0</enable_wind>
        <kinematic>0</kinematic>
      </link>
      <joint name='right_finger' type='prismatic'>
        <pose relative_to='locobot/fingers_link'>0 0 0 0 -0 0</pose>
        <parent>locobot/fingers_link</parent>
        <child>locobot/right_finger_link</child>
        <axis>
          <xyz>0 1 0</xyz>
          <limit>
            <lower>-0.037</lower>
            <upper>-0.015</upper>
            <effort>5</effort>
            <velocity>1</velocity>
          </limit>
          <dynamics>
            <damping>0</damping>
            <friction>0.1</friction>
            <spring_reference>0</spring_reference>
            <spring_stiffness>0</spring_stiffness>
          </dynamics>
        </axis>
      </joint>
      <link name='locobot/right_finger_link'>
        <pose relative_to='right_finger'>0 0 0 0 -0 0</pose>
        <inertial>
          <pose>0.013816 0 0 3.14159 -0 -1.5708</pose>
          <mass>0.016246</mass>
          <inertia>
            <ixx>4.731e-06</ixx>
            <ixy>4.56e-07</ixy>
            <ixz>0</ixz>
            <iyy>1.5506e-06</iyy>
            <iyz>0</iyz>
            <izz>3.7467e-06</izz>
          </inertia>
        </inertial>
        <collision name='locobot/right_finger_link_collision'>
          <pose>0 -0.005 0 3.14159 -0 3.14159</pose>
          <geometry>
            <mesh>
              <scale>0.001 0.001 0.001</scale>
              <uri>/home/bharat/catkin_ws/src/interbotix_ros_rovers/interbotix_ros_xslocobots/interbotix_xslocobot_descriptions/meshes/mobile_wx200_meshes/mobile_wx200_9_gripper_finger.stl</uri>
            </mesh>
          </geometry>
          <surface>
            <contact>
              <ode/>
            </contact>
            <friction>
              <ode/>
              <torsional>
                <ode/>
              </torsional>
            </friction>
            <bounce/>
          </surface>
          <max_contacts>10</max_contacts>
        </collision>
        <visual name='locobot/right_finger_link_visual'>
          <pose>0 -0.005 0 3.14159 -0 3.14159</pose>
          <geometry>
            <mesh>
              <scale>0.001 0.001 0.001</scale>
              <uri>/home/bharat/catkin_ws/src/interbotix_ros_rovers/interbotix_ros_xslocobots/interbotix_xslocobot_descriptions/meshes/mobile_wx200_meshes/mobile_wx200_9_gripper_finger.stl</uri>
            </mesh>
          </geometry>
          <material>
            <script>
              <name>Custom/Interbotix</name>
              <uri>file://media/materials/scripts/gazebo.material</uri>
            </script>
          </material>
        </visual>
        <velocity_decay>
          <linear>0.01</linear>
          <angular>0.01</angular>
        </velocity_decay>
        <self_collide>0</self_collide>
        <enable_wind>0</enable_wind>
        <kinematic>0</kinematic>
      </link>
      <joint name='battery' type='revolute'>
        <pose relative_to='locobot/plate_link'>-0.0345 0 0.010763 0 -0 0</pose>
        <parent>locobot/plate_link</parent>
        <child>locobot/battery_link</child>
        <axis>
          <limit>
            <lower>0</lower>
            <upper>0</upper>
          </limit>
          <dynamics>
            <damping>0</damping>
            <friction>0</friction>
            <spring_reference>0</spring_reference>
            <spring_stiffness>0</spring_stiffness>
          </dynamics>
          <xyz>0 0 1</xyz>
        </axis>
        <physics>
          <ode>
            <limit>
              <cfm>0</cfm>
              <erp>0.2</erp>
            </limit>
          </ode>
        </physics>
      </joint>
      <link name='locobot/battery_link'>
        <pose relative_to='battery'>0 0 0 0 -0 0</pose>
        <inertial>
          <pose>0 0 0.016 0 -0 0</pose>
          <mass>1.194</mass>
          <inertia>
            <ixx>0.004312</ixx>
            <ixy>0</ixy>
            <ixz>0</ixz>
            <iyy>0.001908</iyy>
            <iyz>0</iyz>
            <izz>0.006017</izz>
          </inertia>
        </inertial>
        <collision name='locobot/battery_link_collision'>
          <pose>0 0 0 0 -0 0</pose>
          <geometry>
            <mesh>
              <scale>0.001 0.001 0.001</scale>
              <uri>/home/bharat/catkin_ws/src/interbotix_ros_rovers/interbotix_ros_xslocobots/interbotix_xslocobot_descriptions/meshes/locobot_meshes/locobot_battery.stl</uri>
            </mesh>
          </geometry>
          <surface>
            <contact>
              <ode/>
            </contact>
            <friction>
              <ode/>
              <torsional>
                <ode/>
              </torsional>
            </friction>
            <bounce/>
          </surface>
          <max_contacts>10</max_contacts>
        </collision>
        <visual name='locobot/battery_link_visual'>
          <pose>0 0 0 0 -0 0</pose>
          <geometry>
            <mesh>
              <scale>0.001 0.001 0.001</scale>
              <uri>/home/bharat/catkin_ws/src/interbotix_ros_rovers/interbotix_ros_xslocobots/interbotix_xslocobot_descriptions/meshes/locobot_meshes/locobot_battery.stl</uri>
            </mesh>
          </geometry>
          <material>
            <script>
              <name>Gazebo/Grey</name>
              <uri>file://media/materials/scripts/gazebo.material</uri>
            </script>
          </material>
        </visual>
        <self_collide>0</self_collide>
        <enable_wind>0</enable_wind>
        <kinematic>0</kinematic>
      </link>
      <joint name='left_wheel_joint' type='revolute'>
        <pose relative_to='locobot/base_footprint'>0 0.1165 0.0402 -1.5708 0 0</pose>
        <parent>locobot/base_footprint</parent>
        <child>locobot/left_wheel</child>
        <axis>
          <xyz>0 0 1</xyz>
          <limit>
            <lower>-1e+16</lower>
            <upper>1e+16</upper>
          </limit>
          <dynamics>
            <spring_reference>0</spring_reference>
            <spring_stiffness>0</spring_stiffness>
          </dynamics>
        </axis>
      </joint>
      <link name='locobot/left_wheel'>
        <pose relative_to='left_wheel_joint'>0 0 0 0 -0 0</pose>
        <inertial>
          <pose>0 0 0 0 -0 0</pose>
          <mass>0.2</mass>
          <inertia>
            <ixx>6.76531e-05</ixx>
            <ixy>0</ixy>
            <ixz>0</ixz>
            <iyy>6.76531e-05</iyy>
            <iyz>0</iyz>
            <izz>0.000127806</izz>
          </inertia>
        </inertial>
        <collision name='locobot/left_wheel_collision'>
          <pose>0 0 0 0 -0 0</pose>
          <geometry>
            <cylinder>
              <length>0.015</length>
              <radius>0.03575</radius>
            </cylinder>
          </geometry>
          <max_contacts>10</max_contacts>
          <surface>
            <contact>
              <ode/>
            </contact>
            <bounce/>
            <friction>
              <torsional>
                <ode/>
              </torsional>
              <ode/>
            </friction>
          </surface>
        </collision>
        <visual name='locobot/left_wheel_visual'>
          <pose>0 0 0 0 -0 0</pose>
          <geometry>
            <cylinder>
              <length>0.015</length>
              <radius>0.03575</radius>
            </cylinder>
          </geometry>
        </visual>
        <self_collide>0</self_collide>
        <enable_wind>0</enable_wind>
        <kinematic>0</kinematic>
      </link>
      <joint name='right_wheel_joint' type='revolute'>
        <pose relative_to='locobot/base_footprint'>0 -0.1165 0.0402 -1.5708 0 0</pose>
        <parent>locobot/base_footprint</parent>
        <child>locobot/right_wheel</child>
        <axis>
          <xyz>0 0 1</xyz>
          <limit>
            <lower>-1e+16</lower>
            <upper>1e+16</upper>
          </limit>
          <dynamics>
            <spring_reference>0</spring_reference>
            <spring_stiffness>0</spring_stiffness>
          </dynamics>
        </axis>
      </joint>
      <link name='locobot/right_wheel'>
        <pose relative_to='right_wheel_joint'>0 0 0 0 -0 0</pose>
        <inertial>
          <pose>0 0 0 0 -0 0</pose>
          <mass>0.2</mass>
          <inertia>
            <ixx>6.76531e-05</ixx>
            <ixy>0</ixy>
            <ixz>0</ixz>
            <iyy>6.76531e-05</iyy>
            <iyz>0</iyz>
            <izz>0.000127806</izz>
          </inertia>
        </inertial>
        <collision name='locobot/right_wheel_collision'>
          <pose>0 0 0 0 -0 0</pose>
          <geometry>
            <cylinder>
              <length>0.015</length>
              <radius>0.03575</radius>
            </cylinder>
          </geometry>
          <max_contacts>10</max_contacts>
          <surface>
            <contact>
              <ode/>
            </contact>
            <bounce/>
            <friction>
              <torsional>
                <ode/>
              </torsional>
              <ode/>
            </friction>
          </surface>
        </collision>
        <visual name='locobot/right_wheel_visual'>
          <pose>0 0 0 0 -0 0</pose>
          <geometry>
            <cylinder>
              <length>0.015</length>
              <radius>0.03575</radius>
            </cylinder>
          </geometry>
        </visual>
        <self_collide>0</self_collide>
        <enable_wind>0</enable_wind>
        <kinematic>0</kinematic>
      </link>
      <static>0</static>
      <plugin name='gazebo_ros_control' filename='libgazebo_ros_control.so'>
        <robotSimType>gazebo_ros_control/DefaultRobotHWSim</robotSimType>
        <legacyModeNS>1</legacyModeNS>
        <robotNamespace>/locobot/</robotNamespace>
      </plugin>
      <plugin name='differential_drive_controller' filename='libgazebo_ros_diff_drive.so'>
        <alwaysOn>1</alwaysOn>
        <legacyMode>0</legacyMode>
        <updateRate>62</updateRate>
        <leftJoint>left_wheel_joint</leftJoint>
        <rightJoint>right_wheel_joint</rightJoint>
        <wheelSeparation>0.233</wheelSeparation>
        <wheelDiameter>0.0715</wheelDiameter>
        <wheelTorque>1.0</wheelTorque>
        <wheelAcceleration>0.9</wheelAcceleration>
        <commandTopic>cmd_vel</commandTopic>
        <odometryTopic>odom</odometryTopic>
        <odometryFrame>locobot/odom</odometryFrame>
        <robotBaseFrame>locobot/base_footprint</robotBaseFrame>
        <publishWheelJointState>1</publishWheelJointState>
        <rosDebugLevel>na</rosDebugLevel>
        <publishWheelTF>0</publishWheelTF>
        <publishOdomTF>1</publishOdomTF>
        <odometrySource>world</odometrySource>
        <publishTf>1</publishTf>
        <robotNamespace>/locobot/</robotNamespace>
      </plugin>
      <plugin name='gazebo_ros_p3d_robot' filename='libgazebo_ros_p3d.so'>
        <alwaysOn>1</alwaysOn>
        <update_rate>62</update_rate>
        <topicName>mobile_base/sim_ground_truth_pose</topicName>
        <namespace>/</namespace>
        <frameName>map</frameName>
        <xyz_offset>0 0 0</xyz_offset>
        <rpy_offset>0.0 0.0 0.0</rpy_offset>
        <gaussian_noise>0.0</gaussian_noise>
        <robotNamespace>/locobot/</robotNamespace>
        <bodyName>locobot/base_footprint</bodyName>
        <xyzOffset>0 0 0</xyzOffset>
        <rpyOffset>0 -0 0</rpyOffset>
        <ignition::corrected_offsets>1</ignition::corrected_offsets>
      </plugin>
      <pose>0 0 0 0 -0 0</pose>
    </model>
    <model name='Model'>
      <link name='link_0'>
        <inertial>
          <mass>1</mass>
          <inertia>
            <ixx>0.166667</ixx>
            <ixy>0</ixy>
            <ixz>0</ixz>
            <iyy>0.166667</iyy>
            <iyz>0</iyz>
            <izz>0.166667</izz>
          </inertia>
          <pose>0 0 0 0 -0 0</pose>
        </inertial>
        <pose>2.16601 0.581718 -0.375 0 -0 0</pose>
        <gravity>1</gravity>
        <self_collide>0</self_collide>
        <kinematic>0</kinematic>
        <enable_wind>0</enable_wind>
        <visual name='visual'>
          <pose>0 0 0 0 -0 0</pose>
          <geometry>
            <mesh>
              <uri>/home/bharat/catkin_ws/src/interbotix_ros_rovers/interbotix_ros_xslocobots/interbotix_xslocobot_gazebo/models/trash_bin/meshes/model.dae</uri>
              <scale>1 1 1</scale>
            </mesh>
          </geometry>
          <material>
            <lighting>1</lighting>
            <script>
              <uri>file://media/materials/scripts/gazebo.material</uri>
              <name>Gazebo/Grey</name>
            </script>
            <shader type='pixel'>
              <normal_map>__default__</normal_map>
            </shader>
          </material>
          <transparency>0</transparency>
          <cast_shadows>1</cast_shadows>
        </visual>
        <collision name='collision'>
          <laser_retro>0</laser_retro>
          <max_contacts>10</max_contacts>
          <pose>0 0 0 0 -0 0</pose>
          <geometry>
            <mesh>
              <uri>/home/bharat/catkin_ws/src/interbotix_ros_rovers/interbotix_ros_xslocobots/interbotix_xslocobot_gazebo/models/trash_bin/meshes/model.dae</uri>
              <scale>1 1 1</scale>
            </mesh>
          </geometry>
          <surface>
            <friction>
              <ode>
                <mu>1</mu>
                <mu2>1</mu2>
                <fdir1>0 0 0</fdir1>
                <slip1>0</slip1>
                <slip2>0</slip2>
              </ode>
              <torsional>
                <coefficient>1</coefficient>
                <patch_radius>0</patch_radius>
                <surface_radius>0</surface_radius>
                <use_patch_radius>1</use_patch_radius>
                <ode>
                  <slip>0</slip>
                </ode>
              </torsional>
            </friction>
            <bounce>
              <restitution_coefficient>0</restitution_coefficient>
              <threshold>1e+06</threshold>
            </bounce>
            <contact>
              <collide_without_contact>0</collide_without_contact>
              <collide_without_contact_bitmask>1</collide_without_contact_bitmask>
              <collide_bitmask>1</collide_bitmask>
              <ode>
                <soft_cfm>0</soft_cfm>
                <soft_erp>0.2</soft_erp>
                <kp>1e+13</kp>
                <kd>1</kd>
                <max_vel>0.01</max_vel>
                <min_depth>0</min_depth>
              </ode>
              <bullet>
                <split_impulse>1</split_impulse>
                <split_impulse_penetration_threshold>-0.01</split_impulse_penetration_threshold>
                <soft_cfm>0</soft_cfm>
                <soft_erp>0.2</soft_erp>
                <kp>1e+13</kp>
                <kd>1</kd>
              </bullet>
            </contact>
          </surface>
        </collision>
      </link>
      <link name='link_1'>
        <inertial>
          <mass>0.000807828</mass>
          <inertia>
            <ixx>7.00888e-07</ixx>
            <ixy>0</ixy>
            <ixz>0</ixz>
            <iyy>7.00888e-07</iyy>
            <iyz>0</iyz>
            <izz>7.00888e-07</izz>
          </inertia>
          <pose>0 0 0 0 -0 0</pose>
        </inertial>
        <pose>-0.241531 0.202851 0.125 0 -0 0</pose>
        <visual name='visual'>
          <pose>0 0 0 0 -0 0</pose>
          <geometry>
            <sphere>
              <radius>0.0465731</radius>
            </sphere>
          </geometry>
          <material>
            <lighting>1</lighting>
            <script>
              <uri>file://media/materials/scripts/gazebo.material</uri>
              <name>Gazebo/Grey</name>
            </script>
            <shader type='pixel'/>
          </material>
          <transparency>0</transparency>
          <cast_shadows>1</cast_shadows>
        </visual>
        <collision name='collision'>
          <laser_retro>0</laser_retro>
          <max_contacts>10</max_contacts>
          <pose>0 0 0 0 -0 0</pose>
          <geometry>
            <sphere>
              <radius>0.046573</radius>
            </sphere>
          </geometry>
          <surface>
            <friction>
              <ode>
                <mu>1</mu>
                <mu2>1</mu2>
                <fdir1>0 0 0</fdir1>
                <slip1>0</slip1>
                <slip2>0</slip2>
              </ode>
              <torsional>
                <coefficient>1</coefficient>
                <patch_radius>0</patch_radius>
                <surface_radius>0</surface_radius>
                <use_patch_radius>1</use_patch_radius>
                <ode>
                  <slip>0</slip>
                </ode>
              </torsional>
            </friction>
            <bounce>
              <restitution_coefficient>0</restitution_coefficient>
              <threshold>1e+06</threshold>
            </bounce>
            <contact>
              <collide_without_contact>0</collide_without_contact>
              <collide_without_contact_bitmask>1</collide_without_contact_bitmask>
              <collide_bitmask>1</collide_bitmask>
              <ode>
                <soft_cfm>0</soft_cfm>
                <soft_erp>0.2</soft_erp>
                <kp>1e+13</kp>
                <kd>1</kd>
                <max_vel>0.01</max_vel>
                <min_depth>0</min_depth>
              </ode>
              <bullet>
                <split_impulse>1</split_impulse>
                <split_impulse_penetration_threshold>-0.01</split_impulse_penetration_threshold>
                <soft_cfm>0</soft_cfm>
                <soft_erp>0.2</soft_erp>
                <kp>1e+13</kp>
                <kd>1</kd>
              </bullet>
            </contact>
          </surface>
        </collision>
        <self_collide>0</self_collide>
        <enable_wind>0</enable_wind>
        <kinematic>0</kinematic>
      </link>
      <link name='link_1_clone'>
        <inertial>
          <mass>0.000807828</mass>
          <inertia>
            <ixx>7.00888e-07</ixx>
            <ixy>0</ixy>
            <ixz>0</ixz>
            <iyy>7.00888e-07</iyy>
            <iyz>0</iyz>
            <izz>7.00888e-07</izz>
          </inertia>
          <pose>0 0 0 0 -0 0</pose>
        </inertial>
        <pose>-0.575084 -0.228906 0.125 0 -0 0</pose>
        <visual name='visual'>
          <pose>0 0 0 0 -0 0</pose>
          <geometry>
            <sphere>
              <radius>0.0465731</radius>
            </sphere>
          </geometry>
          <material>
            <lighting>1</lighting>
            <script>
              <uri>file://media/materials/scripts/gazebo.material</uri>
              <name>Gazebo/Grey</name>
            </script>
            <shader type='pixel'/>
          </material>
          <transparency>0</transparency>
          <cast_shadows>1</cast_shadows>
        </visual>
        <collision name='collision'>
          <laser_retro>0</laser_retro>
          <max_contacts>10</max_contacts>
          <pose>0 0 0 0 -0 0</pose>
          <geometry>
            <sphere>
              <radius>0.046573</radius>
            </sphere>
          </geometry>
          <surface>
            <friction>
              <ode>
                <mu>1</mu>
                <mu2>1</mu2>
                <fdir1>0 0 0</fdir1>
                <slip1>0</slip1>
                <slip2>0</slip2>
              </ode>
              <torsional>
                <coefficient>1</coefficient>
                <patch_radius>0</patch_radius>
                <surface_radius>0</surface_radius>
                <use_patch_radius>1</use_patch_radius>
                <ode>
                  <slip>0</slip>
                </ode>
              </torsional>
            </friction>
            <bounce>
              <restitution_coefficient>0</restitution_coefficient>
              <threshold>1e+06</threshold>
            </bounce>
            <contact>
              <collide_without_contact>0</collide_without_contact>
              <collide_without_contact_bitmask>1</collide_without_contact_bitmask>
              <collide_bitmask>1</collide_bitmask>
              <ode>
                <soft_cfm>0</soft_cfm>
                <soft_erp>0.2</soft_erp>
                <kp>1e+13</kp>
                <kd>1</kd>
                <max_vel>0.01</max_vel>
                <min_depth>0</min_depth>
              </ode>
              <bullet>
                <split_impulse>1</split_impulse>
                <split_impulse_penetration_threshold>-0.01</split_impulse_penetration_threshold>
                <soft_cfm>0</soft_cfm>
                <soft_erp>0.2</soft_erp>
                <kp>1e+13</kp>
                <kd>1</kd>
              </bullet>
            </contact>
          </surface>
        </collision>
        <self_collide>0</self_collide>
        <enable_wind>0</enable_wind>
        <kinematic>0</kinematic>
      </link>
      <link name='link_1_clone_clone'>
        <inertial>
          <mass>0.000807828</mass>
          <inertia>
            <ixx>7.00888e-07</ixx>
            <ixy>0</ixy>
            <ixz>0</ixz>
            <iyy>7.00888e-07</iyy>
            <iyz>0</iyz>
            <izz>7.00888e-07</izz>
          </inertia>
          <pose>0 0 0 0 -0 0</pose>
        </inertial>
        <pose>-1.34939 -0.55566 0.125 0 -0 0</pose>
        <visual name='visual'>
          <pose>0 0 0 0 -0 0</pose>
          <geometry>
            <sphere>
              <radius>0.0465731</radius>
            </sphere>
          </geometry>
          <material>
            <lighting>1</lighting>
            <script>
              <uri>file://media/materials/scripts/gazebo.material</uri>
              <name>Gazebo/Grey</name>
            </script>
            <shader type='pixel'/>
          </material>
          <transparency>0</transparency>
          <cast_shadows>1</cast_shadows>
        </visual>
        <collision name='collision'>
          <laser_retro>0</laser_retro>
          <max_contacts>10</max_contacts>
          <pose>0 0 0 0 -0 0</pose>
          <geometry>
            <sphere>
              <radius>0.046573</radius>
            </sphere>
          </geometry>
          <surface>
            <friction>
              <ode>
                <mu>1</mu>
                <mu2>1</mu2>
                <fdir1>0 0 0</fdir1>
                <slip1>0</slip1>
                <slip2>0</slip2>
              </ode>
              <torsional>
                <coefficient>1</coefficient>
                <patch_radius>0</patch_radius>
                <surface_radius>0</surface_radius>
                <use_patch_radius>1</use_patch_radius>
                <ode>
                  <slip>0</slip>
                </ode>
              </torsional>
            </friction>
            <bounce>
              <restitution_coefficient>0</restitution_coefficient>
              <threshold>1e+06</threshold>
            </bounce>
            <contact>
              <collide_without_contact>0</collide_without_contact>
              <collide_without_contact_bitmask>1</collide_without_contact_bitmask>
              <collide_bitmask>1</collide_bitmask>
              <ode>
                <soft_cfm>0</soft_cfm>
                <soft_erp>0.2</soft_erp>
                <kp>1e+13</kp>
                <kd>1</kd>
                <max_vel>0.01</max_vel>
                <min_depth>0</min_depth>
              </ode>
              <bullet>
                <split_impulse>1</split_impulse>
                <split_impulse_penetration_threshold>-0.01</split_impulse_penetration_threshold>
                <soft_cfm>0</soft_cfm>
                <soft_erp>0.2</soft_erp>
                <kp>1e+13</kp>
                <kd>1</kd>
              </bullet>
            </contact>
          </surface>
        </collision>
        <self_collide>0</self_collide>
        <enable_wind>0</enable_wind>
        <kinematic>0</kinematic>
      </link>
      <static>0</static>
      <allow_auto_disable>1</allow_auto_disable>
      <pose>0.491172 1.10467 0.375 0 -0 0</pose>
    </model>
    <state world_name='default'>
      <sim_time>43 95000000</sim_time>
      <real_time>43 416098222</real_time>
      <wall_time>1678484291 679512571</wall_time>
      <iterations>43095</iterations>
      <model name='Model'>
        <pose>0.491172 1.10467 0.372405 -0 2e-06 -2e-06</pose>
        <scale>1 1 1</scale>
        <link name='link_0'>
          <pose>2.65718 1.68639 -0.002599 -0 2e-06 -2e-06</pose>
          <velocity>0 0 0 0 -0 0</velocity>
          <acceleration>-0.015664 0.007065 0.062632 2.71143 -0.242828 -0.000217</acceleration>
          <wrench>-0.015664 0.007065 0.062632 0 -0 0</wrench>
        </link>
        <link name='link_1'>
          <pose>0.249641 1.30752 0.046573 0 -0 0</pose>
          <velocity>0 0 0 0 -0 0</velocity>
          <acceleration>0 0 0 0 -0 0</acceleration>
          <wrench>0 0 0 0 -0 0</wrench>
        </link>
        <link name='link_1_clone'>
          <pose>-0.083912 0.875764 0.046573 0 -0 0</pose>
          <velocity>0 0 0 0 -0 0</velocity>
          <acceleration>0 0 0 0 -0 0</acceleration>
          <wrench>0 0 0 0 -0 0</wrench>
        </link>
        <link name='link_1_clone_clone'>
          <pose>-0.858218 0.54901 0.046573 0 -0 0</pose>
          <velocity>0 0 0 0 -0 0</velocity>
          <acceleration>0 0 0 0 -0 0</acceleration>
          <wrench>0 0 0 0 -0 0</wrench>
        </link>
      </model>
      <model name='ground_plane'>
        <pose>0 0 0 0 -0 0</pose>
        <scale>1 1 1</scale>
        <link name='link'>
          <pose>0 0 0 0 -0 0</pose>
          <velocity>0 0 0 0 -0 0</velocity>
          <acceleration>0 0 0 0 -0 0</acceleration>
          <wrench>0 0 0 0 -0 0</wrench>
        </link>
      </model>
      <model name='locobot'>
        <pose>-0.001664 0.003521 -0.004286 7e-06 0.090542 -0.020309</pose>
        <scale>1 1 1</scale>
        <link name='locobot/ar_tag_link'>
          <pose>0.472762 -0.006202 0.422776 -4.2e-05 0.100046 -0.020545</pose>
          <velocity>0.00213 -9e-05 -0.000112 0.000402 -0.008293 0.007754</velocity>
          <acceleration>0.379756 -0.27869 -0.44743 -0.355258 1.03092 1.7398</acceleration>
          <wrench>0.006269 -0.0046 -0.007386 0 -0 0</wrench>
        </link>
        <link name='locobot/arm_base_link'>
          <pose>0.101166 0.001431 0.111048 8e-06 0.090543 -0.020309</pose>
          <velocity>0.001167 2.1e-05 -0.001264 0.000221 0.012503 -0.000158</velocity>
          <acceleration>0.0843 0.002992 -0.118778 0.752111 1.24323 -1.48598</acceleration>
          <wrench>0.032007 0.001136 -0.045097 0 -0 0</wrench>
        </link>
        <link name='locobot/arm_cradle_link'>
          <pose>0.009737 0.003288 0.235535 6e-06 0.090539 -0.020309</pose>
          <velocity>0.002685 -7.1e-05 -0.000154 0.000257 0.012589 -0.000222</velocity>
          <acceleration>0.16962 0.017163 -0.043492 0.002356 1.20853 -0.36592</acceleration>
          <wrench>0.00299 0.000303 -0.000767 0 -0 0</wrench>
        </link>
        <link name='locobot/base_footprint'>
          <pose>-0.001664 0.003521 -0.004286 7e-06 0.090542 -0.020309</pose>
          <velocity>-0.000314 -1.2e-05 -2.3e-05 0.000267 0.01248 -9.7e-05</velocity>
          <acceleration>-0.03553 0.006378 -0.053193 0.01774 1.113 -0.129443</acceleration>
          <wrench>-0.090086 0.01617 -0.134871 0 -0 0</wrench>
        </link>
        <link name='locobot/battery_link'>
          <pose>-0.026599 0.004027 0.102569 5e-06 0.09054 -0.020307</pose>
          <velocity>0.001029 -6.6e-05 0.000303 0.000439 0.012419 0.001786</velocity>
          <acceleration>0.033194 0.009099 0.001792 0.16267 1.0984 2.01579</acceleration>
          <wrench>0.039634 0.010864 0.00214 0 -0 0</wrench>
        </link>
        <link name='locobot/bump_front_center'>
          <pose>0.00188 0.003449 0.034753 6e-06 0.09054 -0.020309</pose>
          <velocity>0.000173 -2.2e-05 -6e-05 0.00027 0.012514 -9.7e-05</velocity>
          <acceleration>-0.058106 -0.003079 -0.126341 0.031432 1.1604 -0.127672</acceleration>
          <wrench>-0.005811 -0.000308 -0.012634 0 -0 0</wrench>
        </link>
        <link name='locobot/camera_link'>
          <pose>0.13635 0.018247 0.504667 4e-05 0.138714 -0.019927</pose>
          <velocity>0.006092 -0.000244 -0.001389 3.1e-05 0.005847 -0.001431</velocity>
          <acceleration>0.465005 -0.006798 0.081816 -0.204986 1.50783 -0.544051</acceleration>
          <wrench>0.03348 -0.000489 0.005891 0 -0 0</wrench>
        </link>
        <link name='locobot/camera_tower_link'>
          <pose>-0.040609 0.004311 0.100535 6e-06 0.090541 -0.020309</pose>
          <velocity>0.000993 -3.6e-05 0.000478 0.000284 0.012545 6.7e-05</velocity>
          <acceleration>0.220206 0.003342 0.027859 0.058308 1.17856 0.231311</acceleration>
          <wrench>0.535243 0.008124 0.067715 0 -0 0</wrench>
        </link>
        <link name='locobot/ee_arm_link'>
          <pose>0.485524 -0.006466 0.379734 -4.2e-05 0.100046 -0.020545</pose>
          <velocity>0.002483 1.6e-05 -1.1e-05 0.000386 -0.008276 0.007717</velocity>
          <acceleration>0.336195 -0.074675 -0.461316 0.979749 1.01516 1.5732</acceleration>
          <wrench>0.000336 -7.5e-05 -0.000461 0 -0 0</wrench>
        </link>
        <link name='locobot/ee_gripper_link'>
          <pose>0.535836 -0.0075 0.374686 -4.2e-05 0.100081 -0.020551</pose>
          <velocity>0.00251 -2.1e-05 0.000405 -0.000381 -0.008996 -0.00292</velocity>
          <acceleration>0.366536 -0.249047 -0.516139 -0.458008 1.00146 -1.1326</acceleration>
          <wrench>0.000367 -0.000249 -0.000516 0 -0 0</wrench>
        </link>
        <link name='locobot/fingers_link'>
          <pose>0.508405 -0.006936 0.377441 -4.2e-05 0.100081 -0.020551</pose>
          <velocity>0.002486 6.1e-05 0.000158 -0.000375 -0.008999 -0.002873</velocity>
          <acceleration>0.37357 -0.044043 -0.48891 -0.444872 1.00113 -1.03591</acceleration>
          <wrench>0.000374 -4.4e-05 -0.000489 0 -0 0</wrench>
        </link>
        <link name='locobot/forearm_link'>
          <pose>0.179071 -0.000165 0.409906 -1.2e-05 0.097037 -0.020547</pose>
          <velocity>0.002316 -1.3e-05 -0.001295 -7.3e-05 -0.001313 -0.000118</velocity>
          <acceleration>0.366043 -0.123983 -0.307025 -2.7913 0.001106 2.99663</acceleration>
          <wrench>0.103828 -0.035168 -0.087088 0 -0 0</wrench>
        </link>
        <link name='locobot/front_caster_link'>
          <pose>0.121044 0.001034 0.008643 -1.57076 0.130416 -0.020299</pose>
          <velocity>0.015316 -0.000515 -1.2037 3.08788 -0.582144 3.13287</velocity>
          <acceleration>9.0112 -0.329802 -1216.87 -0.264439 0.010054 -0.532529</acceleration>
          <wrench>0.090112 -0.003298 -12.1687 0 -0 0</wrench>
        </link>
        <link name='locobot/gripper_bar_link'>
          <pose>0.485525 -0.006465 0.37974 -4.2e-05 0.100095 -0.020548</pose>
          <velocity>0.0025 0.000124 -0 -0.000161 -0.009341 0.000887</velocity>
          <acceleration>0.38298 0.139197 -0.464159 -0.001772 1.01391 0.385247</acceleration>
          <wrench>0.013098 0.00476 -0.015874 0 -0 0</wrench>
        </link>
        <link name='locobot/gripper_link'>
          <pose>0.44275 -0.005584 0.384036 -4.1e-05 0.10004 -0.020544</pose>
          <velocity>0.002408 2.4e-05 -0.0004 0.000625 -0.007856 0.008251</velocity>
          <acceleration>0.38252 0.299631 -0.438231 -2.1251 1.09292 0.390236</acceleration>
          <wrench>0.02788 0.021839 -0.03194 0 -0 0</wrench>
        </link>
        <link name='locobot/gripper_prop_link'>
          <pose>0.490996 -0.006578 0.379189 -3.2e-05 0.100045 -0.020544</pose>
          <velocity>0.002515 0.000106 5.3e-05 0.000381 -0.008214 0.007639</velocity>
          <acceleration>0.368986 0.111687 -0.465632 1.5625 0.83597 1.54539</acceleration>
          <wrench>0.001601 0.000485 -0.002021 0 -0 0</wrench>
        </link>
        <link name='locobot/laser_frame_link'>
          <pose>-0.061558 0.004733 0.600728 -7e-06 -0.090545 3.12128</pose>
          <velocity>0.0072 -0.000176 0.000739 0.000346 0.012398 0.000875</velocity>
          <acceleration>0.499086 -0.009951 0.043105 0.050378 1.00005 1.85751</acceleration>
          <wrench>0.097821 -0.00195 0.008448 0 -0 0</wrench>
        </link>
        <link name='locobot/left_finger_link'>
          <pose>0.508853 0.014846 0.377441 -5.8e-05 0.100086 -0.020551</pose>
          <velocity>0.002563 9.4e-05 0.000158 -0.000459 -0.008958 -0.002816</velocity>
          <acceleration>0.54197 -0.14078 -0.5142 2.93999 -0.728085 0.852403</acceleration>
          <wrench>0.008805 -0.002287 -0.008354 0 -0 0</wrench>
        </link>
        <link name='locobot/left_wheel'>
          <pose>0.004336 0.119921 0.035751 -1.57092 0.100828 -0.020319</pose>
          <velocity>0.000307 -3.4e-05 2.2e-05 0.001518 0.009151 -0.002346</velocity>
          <acceleration>-0.01026 -0.009976 0.041132 0.301076 -0.035371 -1.79893</acceleration>
          <wrench>-0.002052 -0.001995 0.008226 0 -0 0</wrench>
        </link>
        <link name='locobot/lidar_tower_link'>
          <pose>-0.070078 0.004907 0.506864 6e-06 0.090544 -0.020308</pose>
          <velocity>0.006024 -0.000151 0.000842 0.000323 0.012484 0.000606</velocity>
          <acceleration>0.457772 -0.018042 0.050841 0.145973 1.11289 1.33003</acceleration>
          <wrench>0.071177 -0.002805 0.007905 0 -0 0</wrench>
        </link>
        <link name='locobot/mouse'>
          <pose>0.102036 0.088474 -0.004556 -0.063241 0.063967 -0.807706</pose>
          <velocity>0.000332 0.000891 -0.002237 0.002162 0.008809 -0.001966</velocity>
          <acceleration>0.153385 0.072189 0.137971 -0.473874 1.46566 -0.291779</acceleration>
          <wrench>0.001534 0.000722 0.00138 0 -0 0</wrench>
        </link>
        <link name='locobot/pan_link'>
          <pose>0.056696 0.002332 0.495352 4e-05 0.090536 -0.019925</pose>
          <velocity>0.005934 -0.000141 -0.000728 0.000106 0.012839 -0.001905</velocity>
          <acceleration>0.477472 0.003929 -0.099044 -1.28921 1.51208 -1.26288</acceleration>
          <wrench>0.047268 0.000389 -0.009805 0 -0 0</wrench>
        </link>
        <link name='locobot/plate_link'>
          <pose>0.006779 0.003349 0.088731 6e-06 0.090546 -0.020308</pose>
          <velocity>0.000865 -3.8e-05 -0.000105 0.000331 0.012396 0.0007</velocity>
          <acceleration>0.014698 0.005199 -0.03532 0.004105 1.03675 -0.110941</acceleration>
          <wrench>0.013841 0.004895 -0.03326 0 -0 0</wrench>
        </link>
        <link name='locobot/right_finger_link'>
          <pose>0.50802 -0.025687 0.377445 -4.7e-05 0.10008 -0.020551</pose>
          <velocity>0.002481 0.000207 0.000185 -0.000248 -0.00898 -0.002987</velocity>
          <acceleration>0.263527 -0.099562 -0.493873 -0.94087 0.759139 0.316907</acceleration>
          <wrench>0.004281 -0.001617 -0.008023 0 -0 0</wrench>
        </link>
        <link name='locobot/right_wheel'>
          <pose>-0.000396 -0.113028 0.035751 -1.57069 0.043229 -0.020306</pose>
          <velocity>0.000287 -1.1e-05 2.7e-05 -0.000252 0.008571 0.002223</velocity>
          <acceleration>-0.028654 0.016228 0.032943 -0.455955 -0.293871 1.80533</acceleration>
          <wrench>-0.005731 0.003246 0.006589 0 -0 0</wrench>
        </link>
        <link name='locobot/shoulder_link'>
          <pose>0.107149 0.00131 0.176952 -1.2e-05 0.090541 -0.020547</pose>
          <velocity>0.001992 4e-06 -0.001338 0.000205 0.012507 -0.000199</velocity>
          <acceleration>0.127897 0.003431 -0.122702 -0.155436 1.06306 -1.10574</acceleration>
          <wrench>0.061503 0.00165 -0.059005 0 -0 0</wrench>
        </link>
        <link name='locobot/tilt_link'>
          <pose>0.083341 0.0018 0.512011 4.1e-05 0.13871 -0.01992</pose>
          <velocity>0.006122 -0.000195 -0.001073 -2.3e-05 0.005871 -0.001823</velocity>
          <acceleration>0.46226 -0.036661 -0.010025 1.14237 -0.572683 1.46712</acceleration>
          <wrench>0.009174 -0.000728 -0.000199 0 -0 0</wrench>
        </link>
        <link name='locobot/upper_arm_link'>
          <pose>0.110642 0.001238 0.215444 -1.3e-05 0.093447 -0.020548</pose>
          <velocity>0.002513 -5e-06 -0.001384 -5.5e-05 -0.001101 -0.000129</velocity>
          <acceleration>0.319277 0.039516 -0.152254 -3.001 1.04681 2.87619</acceleration>
          <wrench>0.095075 0.011767 -0.045338 0 -0 0</wrench>
        </link>
        <link name='locobot/wrist_link'>
          <pose>0.378088 -0.004255 0.390529 -1.2e-05 0.100049 -0.020547</pose>
          <velocity>0.002343 -6.5e-05 -0.00099 0.000127 -0.008818 0.00296</velocity>
          <acceleration>0.36748 0.008229 -0.407854 1.3361 0.296178 -0.278237</acceleration>
          <wrench>0.03122 0.000699 -0.03465 0 -0 0</wrench>
        </link>
      </model>
      <model name='maze'>
        <pose>0.515 0.725 0 0 -0 0</pose>
        <scale>1 1 1</scale>
        <link name='Wall_1'>
          <pose>0.515 -0.95 0 0 -0 0</pose>
          <velocity>0 0 0 0 -0 0</velocity>
          <acceleration>0 0 0 0 -0 0</acceleration>
          <wrench>0 0 0 0 -0 0</wrench>
        </link>
        <link name='Wall_2'>
          <pose>3.94 0.725 0 0 -0 1.5708</pose>
          <velocity>0 0 0 0 -0 0</velocity>
          <acceleration>0 0 0 0 -0 0</acceleration>
          <wrench>0 0 0 0 -0 0</wrench>
        </link>
        <link name='Wall_3'>
          <pose>0.515 2.4 0 0 -0 3.14159</pose>
          <velocity>0 0 0 0 -0 0</velocity>
          <acceleration>0 0 0 0 -0 0</acceleration>
          <wrench>0 0 0 0 -0 0</wrench>
        </link>
        <link name='Wall_4'>
          <pose>-2.91 0.725 0 0 0 -1.5708</pose>
          <velocity>0 0 0 0 -0 0</velocity>
          <acceleration>0 0 0 0 -0 0</acceleration>
          <wrench>0 0 0 0 -0 0</wrench>
        </link>
        <link name='Wall_6'>
          <pose>1.61 0.725 0 0 0 -1.5708</pose>
          <velocity>0 0 0 0 -0 0</velocity>
          <acceleration>0 0 0 0 -0 0</acceleration>
          <wrench>0 0 0 0 -0 0</wrench>
        </link>
      </model>
      <light name='sun'>
        <pose>0 0 10 0 -0 0</pose>
      </light>
    </state>
  </world>
</sdf>
